Workbook

Sheet 목표 간트
A2: Abyss 경쟁력 목표 간트
A3: 두 폼을 연결하는 전투와 형체에 남은 사람들의 이야기 | 기준 2026-09-26
A4: 기간은 가용 시간 미확인 가안. 선행 조건 우선. P01에서 자원을 확인하고 PG2에서 일정을 다시 산정한다.
A5: 목표 상세 G~I열 입력 → 결과 자동 반영. 파랑: 제작 / 보라: 사용자 관문. 기존 완료 내역은 뒤쪽 시트에 보존.
A6: ID | B6: 플레이어 경험 목표 | C6: 우선순위 | D6: 2026 Q4 | E6: 2027 Q1 | F6: 2027 Q2 | G6: 2027 Q3 | H6: 2027 Q4 | I6: 2028 상반기 | J6: 2028 하반기 | K6: 선행 조건 | L6: 판정
A7: P01 | B7: 대표 경험과 제작 범위 확정 | C7: P0 | D7: 계획 | K7: 없음 | L7: ='목표 상세'!J7
A8: P02 | B8: 스크롤 맵 A1~A4 연결 | C8: P0 | D8: 계획 | K8: P01 | L8: ='목표 상세'!J8
A9: P03 | B9: 4폼의 전투 역할 구별 | C9: P0 | D9: 계획 | K9: P01 | L9: ='목표 상세'!J9
A10: P04 | B10: 상황에 맞는 폼 교체 | C10: P0 | D10: 계획 | K10: P03 | L10: ='목표 상세'!J10
A11: P05 | B11: 행동이 다른 빌드 3종 | C11: P0 | D11: 계획 | E11: 계획 | K11: P03, P04 | L11: ='목표 상세'!J11
A12: P06 | B12: 두 폼을 성장시키는 드래프트 | C12: P0 | D12: 계획 | E12: 계획 | K12: P04 | L12: ='목표 상세'!J12
A13: P07 | B13: 지형과 적 조합의 전술 차이 | C13: P0 | D13: 계획 | E13: 계획 | K13: P02, P03 | L13: ='목표 상세'!J13
A14: P08 | B14: 대표 화면·전투 소리·보스 가독성 | C14: P0 | D14: 계획 | E14: 계획 | K14: P02, P03 | L14: ='목표 상세'!J14
A15: PG1 | B15: 대표 구간 재미 확인 | C15: 관문 | E15: 판정 | K15: P01, P02, P03, P04, P05, P06, P07, P08 | L15: ='목표 상세'!J15
A16: P09 | B16: 무기 보상의 역할 확정 | C16: P1 | E16: 계획 | K16: PG1 | L16: ='목표 상세'!J16
A17: P10 | B17: 런 경제와 영구 성장 균형 | C17: P1 | E17: 계획 | K17: PG1, P09 | L17: ='목표 상세'!J17
A18: P11 | B18: 폼 내력과 반복 서사 연결 | C18: P1 | E18: 계획 | K18: PG1 | L18: ='목표 상세'!J18
A19: P12 | B19: 첫 플레이와 기본 접근성 | C19: P1 | D19: 계획 | E19: 계획 | K19: P01 | L19: ='목표 상세'!J19
A20: PG2 | B20: 반복 플레이와 제작성 확인 | C20: 관문 | E20: 판정 | K20: PG1, P09, P10, P11, P12 | L20: ='목표 상세'!J20
A21: P13 | B21: 차별점이 보이는 데모와 소개 | C21: P1 | F21: 계획 | K21: PG2 | L21: ='목표 상세'!J21
A22: P14 | B22: 가격·공개 범위·시장 반응 기준 | C22: P1 | F22: 계획 | K22: PG2 | L22: ='목표 상세'!J22
A23: PG3 | B23: 데모 공개 준비와 시장 신호 | C23: 관문 | F23: 판정 | K23: P13, P14, P12 | L23: ='목표 상세'!J23
A24: P15 | B24: EA 콘텐츠 범위와 제작 여유 | C24: P1 | F24: 계획 | G24: 계획 | K24: PG2 | L24: ='목표 상세'!J24
A25: P16 | B25: EA 저장·성능·입력·번역 품질 | C25: P0 | F25: 계획 | G25: 계획 | K25: PG2, P12 | L25: ='목표 상세'!J25
A26: PG4 | B26: EA 출시 결정 | C26: 관문 | G26: 판정 | K26: PG3, P15, P16 | L26: ='목표 상세'!J26
A27: P17 | B27: EA 운영과 첫 개선 주기 | C27: P1 | H27: 계획 | K27: PG4 | L27: ='목표 상세'!J27
A28: P18 | B28: 후반 콘텐츠와 서사 회수 | C28: P2 | I28: 계획 | J28: 계획 | K28: P17 | L28: ='목표 상세'!J28
A29: P19 | B29: 정식판 마무리와 지원 범위 | C29: P1 | J29: 계획 | K29: P18, P16 | L29: ='목표 상세'!J29
A30: PG5 | B30: v1.0 출시 결정 | C30: 관문 | J30: 판정 | K30: P19 | L30: ='목표 상세'!J30

Sheet 목표 상세
A2: 목표별 완료 기준과 확인 근거
A3: 노란색 G~I열만 진행 입력. 산출물 완료 + 사용자 통과 + 근거 기록 + 선행 목표 통과가 모두 있어야 최종 통과.
A4: 사람 플레이·테스트·빌드·공개는 사용자 담당. 계획 작성은 구현 완료가 아니다. 기존 플레이테스트 보류 정책 유지.
A5: PG1~PG5는 신규 제품 판단 관문. 숫자는 내부 탐색 목표이며 기존 G1/G2/G4 판정 기준과 별도로 관리한다.
A6: ID | B6: 우선순위 | C6: 목표 | D6: 시작 가안 | E6: 종료 가안 | F6: 선행 목표 | G6: 산출물 상태 | H6: 사용자 판정 | I6: 확인 근거 / 기록 위치 | J6: 최종 판정 | K6: 만들 결과 | L6: 완료 기준 | M6: 미달 시 조치 | N6: 근거 문서 / 기존 작업
A7: P01 | B7: P0 | C7: 대표 경험과 제작 범위 확정 | D7: 2026 Q4 | E7: 2026 Q4 | F7: 없음 | G7: 미착수 | H7: 미검증 | J7: =IF(G7="보류","보류",IF(H7="미달","보완 필요",IF(AND(G7="산출물 완료",H7="통과",I7<>""),IF(TRUE,"통과","선행 미통과"),"미검증"))) | K7: 두 폼을 연결해 싸우며 남겨진 사람들의 형체를 이어받는 경험. 기존 4폼·18스킬·Stage1을 대표 구간의 기본 범위로 삼는다. | L7: 15~20분 대표 구간의 시작·보스·종료 범위, 핵심 고객, 제외 항목, 주당 제작 시간과 외주 예산을 기록한다. 기존 3스테이지는 보존한다. | M7: 범위가 자원을 넘으면 신규 폼·스테이지 확장을 미룬다. | N7: 00 콘셉트 / 08 콘텐츠 로드맵 / 현재 에셋
A8: P02 | B8: P0 | C8: 스크롤 맵 A1~A4 연결 | D8: 2026 Q4 | E8: 2026 Q4 | F8: P01 | G8: 산출물 완료 | H8: 통과 | I8: 2026-10-02 사용자: 플레이했을 때 진행 흐름이 정상적으로 작동 중이라고 확인. AI 테스트/Unity 실행 없음. P01 선행 판정은 별도. | J8: =IF(G8="보류","보류",IF(H8="미달","보완 필요",IF(AND(G8="산출물 완료",H8="통과",I8<>""),IF(AND($J$7="통과"),"통과","선행 미통과"),"미검증"))) | K8: 자유 이동, 배치 스폰, 조건부 추가 소환, 전멸 후 맵 끝 보상 문, 전환 페이드. 결계는 사용하지 않는다. | L8: Stage1 대표 경로에서 진입·교전·추가 소환·보상·다음 방·보스까지 막힘 없이 연결한다. 기존 아레나 방의 호환을 유지한다. | M8: 진행 오류부터 수정하고 추가 방 제작을 멈춘다. | N8: 17 스테이지·보스 연출 / 기존 스크롤 맵 행
A9: P03 | B9: P0 | C9: 4폼의 전투 역할 구별 | D9: 2026 Q4 | E9: 2026 Q4 | F9: P01 | G9: 미착수 | H9: 미검증 | J9: =IF(G9="보류","보류",IF(H9="미달","보완 필요",IF(AND(G9="산출물 완료",H9="통과",I9<>""),IF(AND($J$7="통과"),"통과","선행 미통과"),"미검증"))) | K9: 검사의 근접 압박, 방패의 방어·반격, 궁수와 투척사의 거리·타이밍 차이를 정의하고 구현한다. | L9: 동일 교전에서 각 폼의 장점과 대가를 1개 이상 관찰한다. 궁수·투척사는 그림과 피해량 외에 사거리 운용·발사 방식·위험 중 하나 이상이 다르다. | M9: 구별되지 않는 폼을 재설계하고 신규 폼을 추가하지 않는다. | N9: 02 폼 / 15 원거리 / 16 가드 / FormData
A10: P04 | B10: P0 | C10: 상황에 맞는 폼 교체 | D10: 2026 Q4 | E10: 2026 Q4 | F10: P03 | G10: 미착수 | H10: 미검증 | J10: =IF(G10="보류","보류",IF(H10="미달","보완 필요",IF(AND(G10="산출물 완료",H10="통과",I10<>""),IF(AND($J$9="통과"),"통과","선행 미통과"),"미검증"))) | K10: 가드 후 진입, 거리 전환, 표식 소비 등 공통 연결 규칙 후보를 비교해 최대 2개만 시범 적용한다. 특정 후보는 아직 확정하지 않는다. | L10: 두 폼 조합 2쌍 이상에서 서로 다른 교체 이유가 관찰된다. 고정 폼·무조건 쿨마다 교체·상황별 교체를 비교하고 단순 피해 보너스 반복 여부를 기록한다. | M10: 효과를 더 붙이기 전에 연결 규칙과 적 배치를 수정한다. | N10: 심연 충전 / FormController / 2026-09-26 분석
A11: P05 | B11: P0 | C11: 행동이 다른 빌드 3종 | D11: 2026 Q4 | E11: 2027 Q1 | F11: P03, P04 | G11: 미착수 | H11: 미검증 | J11: =IF(G11="보류","보류",IF(H11="미달","보완 필요",IF(AND(G11="산출물 완료",H11="통과",I11<>""),IF(AND($J$9="통과",$J$10="통과"),"통과","선행 미통과"),"미검증"))) | K11: 교체 공격·대시 잔상·가드 반격의 3빌드를 기존 스킬 중심으로 구성한다. 부족한 연결 스킬만 제한적으로 추가한다. | L11: 같은 방에서 공격 순서·이동 경로·위험 감수 중 2가지 이상이 빌드별로 달라진다. 초반 선택 2~3회 안에 변화가 드러나는지 확인한다. | M11: 스킬 총량 확대를 멈추고 선택의 효과와 설명을 수정한다. | N11: 03 드래프트 / PlayerCharacter.Passives·Synergy
A12: P06 | B12: P0 | C12: 두 폼을 성장시키는 드래프트 | D12: 2026 Q4 | E12: 2027 Q1 | F12: P04 | G12: 미착수 | H12: 미검증 | J12: =IF(G12="보류","보류",IF(H12="미달","보완 필요",IF(AND(G12="산출물 완료",H12="통과",I12<>""),IF(AND($J$10="통과"),"통과","선행 미통과"),"미검증"))) | K12: 활성 폼 기준 현행 추첨과 보유 두 폼 기준 후보안을 비교한다. 시너지 가중치·교체 손실·공용 스킬 노출을 함께 다룬다. | L12: 레벨업 직전 폼 전환이 성장의 필수 요령이 되지 않는다. 죽은 선택지·한 폼 쏠림을 제시/선택 로그와 관찰로 비교하고 채택 규칙을 남긴다. | M12: 수치 조정만 반복하지 말고 추첨 대상과 정보 제공을 재검토한다. | N12: DraftWeightCalculator / draft_offered 계측
A13: P07 | B13: P0 | C13: 지형과 적 조합의 전술 차이 | D13: 2026 Q4 | E13: 2027 Q1 | F13: P02, P03 | G13: 미착수 | H13: 미검증 | J13: =IF(G13="보류","보류",IF(H13="미달","보완 필요",IF(AND(G13="산출물 완료",H13="통과",I13<>""),IF(AND($J$8="통과",$J$9="통과"),"통과","선행 미통과"),"미검증"))) | K13: 고저차·엄폐·원거리 압박을 활용한 대표 교전 3종. 잠복·천장·부유 적은 이 교전의 필요에 따라 선택 제작한다. | L13: 3교전이 서로 다른 접근·우선 처치·퇴각 판단을 요구한다. 특정 폼 없이는 진행 불가한 배치를 피하고 공격 예고·안전 경로를 읽을 수 있다. | M13: 적 종류를 늘리기 전에 배치와 예고를 바꾼다. | N13: 17 스테이지 / 환경 활용형 적 3종 기존 행
A14: P08 | B14: P0 | C14: 대표 화면·전투 소리·보스 가독성 | D14: 2026 Q4 | E14: 2027 Q1 | F14: P02, P03 | G14: 미착수 | H14: 미검증 | J14: =IF(G14="보류","보류",IF(H14="미달","보완 필요",IF(AND(G14="산출물 완료",H14="통과",I14<>""),IF(AND($J$8="통과",$J$9="통과"),"통과","선행 미통과"),"미검증"))) | K14: 실제 해상도에서 캐릭터·배경·무기·판정의 화풍과 대비를 통일한다. 플레이어 피격·저스트 가드·교체·보스 예고의 소리를 구별한다. | L14: 대표 구간 아트·핵심 시나리오 준비를 사용자 확인한다. 보스 예고→발동→회복이 보이고 시너지 효과가 예고를 가리지 않는다. 음소거/소리 켬 모두 관찰한다. | M14: 이펙트와 장식을 줄여 정보 전달부터 복구한다. | N14: 아트 바이블 / BossPresenter / wave2 사운드 잔여
A15: PG1 | B15: 관문 | C15: 대표 구간 재미 확인 | D15: 2027 Q1 | E15: 2027 Q1 | F15: P01, P02, P03, P04, P05, P06, P07, P08 | G15: 미착수 | H15: 미검증 | J15: =IF(G15="보류","보류",IF(H15="미달","보완 필요",IF(AND(G15="산출물 완료",H15="통과",I15<>""),IF(AND($J$7="통과",$J$8="통과",$J$9="통과",$J$10="통과",$J$11="통과",$J$12="통과",$J$13="통과",$J$14="통과"),"통과","선행 미통과"),"미검증"))) | K15: 기존 플레이테스트 보류 정책을 유지한다. 대표 구간 아트·시나리오 준비 후 사용자가 테스트 재개를 결정한다. | L15: 신규 장르 경험자 8명씩 2회 탐색 테스트. 각 회차 6/8 이상이 유도 없이 상황별 교체 이유를 설명하고, 5/8 이상이 시간이 제공된 자유 선택에서 재도전한다. 사망 원인 혼동 반복은 수정한다. | M15: 대표 구간을 보완하고 새로운 참가자에게 재확인한다. 수치만 맞추려고 기준을 사후 변경하지 않는다. | N15: 18 경쟁력 목표 §검증 / 기존 P-24 보류 정책
A16: P09 | B16: P1 | C16: 무기 보상의 역할 확정 | D16: 2027 Q1 | E16: 2027 Q1 | F16: PG1 | G16: 미착수 | H16: 미검증 | J16: =IF(G16="보류","보류",IF(H16="미달","보완 필요",IF(AND(G16="산출물 완료",H16="통과",I16<>""),IF(AND($J$15="통과"),"통과","선행 미통과"),"미검증"))) | K16: 현재 폼당 1무기의 강화 보상과 같은 폼 내 선택 후보를 비교한다. 동작은 폼이 소유한다는 기존 정책을 유지한다. | L16: 강화 중심이면 구매·가격·보상 체감을 개선하고 독립 빌드 축으로 홍보하지 않는다. 선택형이면 대표 폼에서 조건부 효과와 대가가 다른 2종을 비교한 후 확장 여부를 결정한다. | M16: 의미 없는 상위호환 무기 추가를 보류한다. | N16: 14 무기 장비 / WeaponData / 무기 가격 밸런스 행
A17: P10 | B17: P1 | C17: 런 경제와 영구 성장 균형 | D17: 2027 Q1 | E17: 2027 Q1 | F17: PG1, P09 | G17: 미착수 | H17: 미검증 | J17: =IF(G17="보류","보류",IF(H17="미달","보완 필요",IF(AND(G17="산출물 완료",H17="통과",I17<>""),IF(AND($J$15="통과",$J$16="통과"),"통과","선행 미통과"),"미검증"))) | K17: 회복·무기·리롤·유물의 기회비용과 신규/성장 세이브 난이도를 정리한다. | L17: 스킬 강제 파밍 없이 숙련으로 개선 가능하다. 상점에서 항상 같은 구매만 하는지, 손실 회복 불가 구간과 과도한 눈덩이가 있는지 비교한다. 수치는 관측 뒤 조정한다. | M17: 보상량과 가격·성장 폭부터 조정하고 통화를 추가하지 않는다. | N17: RunConfig / MetaUpgrades / 기존 밸런스 시트 행
A18: P11 | B18: P1 | C18: 폼 내력과 반복 서사 연결 | D18: 2027 Q1 | E18: 2027 Q1 | F18: PG1 | G18: 미착수 | H18: 미검증 | J18: =IF(G18="보류","보류",IF(H18="미달","보완 필요",IF(AND(G18="산출물 완료",H18="통과",I18<>""),IF(AND($J$15="통과"),"통과","선행 미통과"),"미검증"))) | K18: 각인사 내력, 짧은 환경 흔적, 보스 대사를 대표 경로에 연결한다. 전면 반응형 대사 시스템은 범위 밖이다. | L18: 소설을 읽지 않은 사용자가 현재 목적과 폼에 남은 인물 1명을 자신의 말로 설명한다. 대화 건너뛰기로 진행이 막히지 않고 반복 텍스트가 전투 리듬을 끊지 않는다. | M18: 세계관 설명을 늘리기 전에 목적과 인물 노출 위치를 수정한다. | N18: 10 서사 / 11 각인사 / 12 프롤로그·엔딩
A19: P12 | B19: P1 | C19: 첫 플레이와 기본 접근성 | D19: 2026 Q4 | E19: 2027 Q1 | F19: P01 | G19: 미착수 | H19: 미검증 | J19: =IF(G19="보류","보류",IF(H19="미달","보완 필요",IF(AND(G19="산출물 완료",H19="통과",I19<>""),IF(AND($J$7="통과"),"통과","선행 미통과"),"미검증"))) | K19: 이동·회피·교체·드래프트를 플레이로 익히는 도입. 키보드/패드 포커스, 기본 키 변경, 글자·대비·흔들림 옵션을 데모 전 범위로 당긴다. | L19: 처음 접한 사용자가 구두 도움 없이 첫 전투와 첫 선택을 마친다. 핵심 흐름을 키보드/패드만으로 조작하고 필수 정보가 색만으로 구분되지 않는다. | M19: 안내 문장을 늘리기 전에 조작·표시·학습 순서를 수정한다. | N19: 기존 키 리바인딩·접근성 행 / UI 잔여
A20: PG2 | B20: 관문 | C20: 반복 플레이와 제작성 확인 | D20: 2027 Q1 | E20: 2027 Q1 | F20: PG1, P09, P10, P11, P12 | G20: 미착수 | H20: 미검증 | J20: =IF(G20="보류","보류",IF(H20="미달","보완 필요",IF(AND(G20="산출물 완료",H20="통과",I20<>""),IF(AND($J$15="통과",$J$16="통과",$J$17="통과",$J$18="통과",$J$19="통과"),"통과","선행 미통과"),"미검증"))) | K20: 같은 8명 이상이 3런씩 플레이하고 빌드·경로·실패 학습을 비교한다. 대표 콘텐츠의 실제 제작 시간을 기록한다. | L20: 6/8 이상이 3런 중 2개 이상의 다른 운용을 시도하고 차이를 설명한다. 반복 불만과 항상 고르는 선택을 기록한다. 신규 제작 단가와 수정 시간을 반영해 EA 범위를 다시 산정한다. | M20: 소모 속도보다 새 콘텐츠 제작이 느리면 범위를 축소하고 기존 교전의 조합을 개선한다. | N20: 18 경쟁력 목표 / 기존 외부 플레이테스트 행
A21: P13 | B21: P1 | C21: 차별점이 보이는 데모와 소개 | D21: 2027 Q2 | E21: 2027 Q2 | F21: PG2 | G21: 미착수 | H21: 미검증 | J21: =IF(G21="보류","보류",IF(H21="미달","보완 필요",IF(AND(G21="산출물 완료",H21="통과",I21<>""),IF(AND($J$20="통과"),"통과","선행 미통과"),"미검증"))) | K21: 15~20분 대표 데모와 실제 전투 30초 소개 영상. 두 폼 연결 장면·빌드 변화·인물 흔적을 보여준다. | L21: 첫 노출 장르 경험자 10명 중 7명 이상이 유도 없이 폼을 연결하는 특징을 설명한다. 미구현 기능을 광고하지 않고 기존 경쟁작과 구별되는 장면을 1개 이상 회상한다. | M21: 콘텐츠 수 광고를 늘리기 전에 보여줄 장면과 도입을 수정한다. | N21: 00 콘셉트 / Steam 페이지 기존 행 / 18 경쟁력 목표
A22: P14 | B22: P1 | C22: 가격·공개 범위·시장 반응 기준 | D22: 2027 Q2 | E22: 2027 Q2 | F22: PG2 | G22: 미착수 | H22: 미검증 | J22: =IF(G22="보류","보류",IF(H22="미달","보완 필요",IF(AND(G22="산출물 완료",H22="통과",I22<>""),IF(AND($J$20="통과"),"통과","선행 미통과"),"미검증"))) | K22: EA 가격 후보, 제공 범위, 개발 예산·남은 기간, 체험판 피드백 창구와 유입별 지표를 확정한다. 외부 공개는 사용자 실행 단계다. | L22: 가격별 제공 가치와 비용 회수 가정을 기록한다. 방문·데모 시작·플레이·위시리스트를 혼합하지 않고 정의한다. 결과 확인 전에 테스트 기간·유입·표본·재검토 기준을 정한다. | M22: 유입 부족과 제품 반응 부족을 구별하고 고정 판매량 목표만으로 출시하지 않는다. | N22: 00 콘셉트 성공 기준 / 기존 Steam 페이지 행
A23: PG3 | B23: 관문 | C23: 데모 공개 준비와 시장 신호 | D23: 2027 Q2 | E23: 2027 Q2 | F23: P13, P14, P12 | G23: 미착수 | H23: 미검증 | J23: =IF(G23="보류","보류",IF(H23="미달","보완 필요",IF(AND(G23="산출물 완료",H23="통과",I23<>""),IF(AND($J$21="통과",$J$22="통과",$J$19="통과"),"통과","선행 미통과"),"미검증"))) | K23: 사용자가 공개를 결정한 뒤 데모 피드백을 수집한다. 행사 일정·참가 조건은 신청 시점에 공식 정보로 다시 확인한다. | L23: P13의 차별점 전달 기준과 P14의 사전 정의 기준을 평가한다. 출시 진행 불가 오류가 없고 외부 사용자에게 기본 입력·언어 흐름이 작동한다. 노출 부족이면 미판정으로 남긴다. | M23: 반응 근거가 없으면 신규 대량 제작과 출시 확정을 보류한다. | N23: Steam 페이지 / Next Fest 기존 행 / 18 경쟁력 목표
A24: P15 | B24: P1 | C24: EA 콘텐츠 범위와 제작 여유 | D24: 2027 Q2 | E24: 2027 Q3 | F24: PG2 | G24: 미착수 | H24: 미검증 | J24: =IF(G24="보류","보류",IF(H24="미달","보완 필요",IF(AND(G24="산출물 완료",H24="통과",I24<>""),IF(AND($J$20="통과"),"통과","선행 미통과"),"미검증"))) | K24: 기존 3스테이지를 기본으로 품질을 맞춘다. 추가 2폼·Stage4~5·스킬 확대는 검증과 제작 여력에 따라 선택한다. | L24: 각 추가 콘텐츠가 새 판단을 만드는 이유를 설명한다. 측정된 제작·수정 시간으로 남은 일정을 계산하고 가용 시간의 25%를 수정·QA 여유로 둔다. 80스킬을 출시 필수로 삼지 않는다. | M24: 날짜에 맞춰 품질을 낮추지 말고 선택 콘텐츠를 미룬다. | N24: 08 콘텐츠 수량 후보 / PG2 제작 시간
A25: P16 | B25: P0 | C25: EA 저장·성능·입력·번역 품질 | D25: 2027 Q2 | E25: 2027 Q3 | F25: PG2, P12 | G25: 미착수 | H25: 미검증 | J25: =IF(G25="보류","보류",IF(H25="미달","보완 필요",IF(AND(G25="산출물 완료",H25="통과",I25<>""),IF(AND($J$20="통과",$J$19="통과"),"통과","선행 미통과"),"미검증"))) | K25: 최소 지원 PC·해상도·언어를 정하고 신규/기존 세이브·실패 복구·긴 런·패드·재시작·완주를 확인한다. | L25: 저장 손실·진행 불가·충돌의 재현 미해결 건이 없다. 지정 최소 사양에서 60fps 목표와 프레임 지연을 측정한다. 핵심 콘텐츠 이름·설명과 보스 대사의 지원 언어 누락을 정리한다. | M25: 공개 범위를 줄이거나 출시를 연기한다. 코드 존재만으로 통과 처리하지 않는다. | N25: 저장·현지화 NEXT_TASKS / 기존 Steam Cloud·QA 행
A26: PG4 | B26: 관문 | C26: EA 출시 결정 | D26: 2027 Q3 | E26: 2027 Q3 | F26: PG3, P15, P16 | G26: 미착수 | H26: 미검증 | J26: =IF(G26="보류","보류",IF(H26="미달","보완 필요",IF(AND(G26="산출물 완료",H26="통과",I26<>""),IF(AND($J$23="통과",$J$24="통과",$J$25="통과"),"통과","선행 미통과"),"미검증"))) | K26: 기존 2027 Q3는 조건부 목표 창이다. 공개 범위·가격·알려진 한계·지원 계획을 사용자 확인 후 출시한다. | L26: 선행 목표 통과, 공개 약속과 빌드 일치, 실제 시장 반응과 자금·일정 검토, 저장/진행 치명 오류 미해결 0건. 리뷰율·판매량은 출시 후 관측값이며 출시 전 통과 조건으로 쓰지 않는다. | M26: 선택 콘텐츠를 줄이거나 출시 창을 재산정한다. | N26: 기존 EA 출시 행 / 18 경쟁력 목표
A27: P17 | B27: P1 | C27: EA 운영과 첫 개선 주기 | D27: 2027 Q4 | E27: 2027 Q4 | F27: PG4 | G27: 미착수 | H27: 미검증 | J27: =IF(G27="보류","보류",IF(H27="미달","보완 필요",IF(AND(G27="산출물 완료",H27="통과",I27<>""),IF(AND($J$26="통과"),"통과","선행 미통과"),"미검증"))) | K27: 리뷰·중단 구간·폼/스킬 선택·오류를 함께 보고 첫 패치 우선순위를 정한다. | L27: 상위 반복 문제 3개에 대해 원인·변경·확인 결과를 남긴다. 패치 전후 빌드와 표본 조건을 구별한다. 30일 리텐션만으로 유료 싱글 게임의 성공을 판정하지 않는다. | M27: 새 콘텐츠보다 진행·가독성·밸런스 문제를 먼저 수정한다. | N27: 기존 1차 메이저 패치 행
A28: P18 | B28: P2 | C28: 후반 콘텐츠와 서사 회수 | D28: 2028 상반기 | E28: 2028 하반기 | F28: P17 | G28: 미착수 | H28: 미검증 | J28: =IF(G28="보류","보류",IF(H28="미달","보완 필요",IF(AND(G28="산출물 완료",H28="통과",I28<>""),IF(AND($J$27="통과"),"통과","선행 미통과"),"미검증"))) | K28: 남은 Act와 엔딩을 완성한다. 피의 서약·영혼 축·히든 폼은 추가 운용과 서사 회수 가치가 있을 때 제작한다. | L28: 주인공의 귀환 목표와 각인사·기록자의 서사 약속을 게임 안에서 회수한다. 기존 10폼·150스킬·히든 모드는 상한 후보이며 전부 필수는 아니다. | M28: 새 시스템을 추가하지 말고 기존 서사의 미회수와 후반 반복부터 고친다. | N28: 10 서사 / 12 엔딩 / M4 콘텐츠 후보
A29: P19 | B29: P1 | C29: 정식판 마무리와 지원 범위 | D29: 2028 하반기 | E29: 2028 하반기 | F29: P18, P16 | G29: 미착수 | H29: 미검증 | J29: =IF(G29="보류","보류",IF(H29="미달","보완 필요",IF(AND(G29="산출물 완료",H29="통과",I29<>""),IF(AND($J$28="통과",$J$25="통과"),"통과","선행 미통과"),"미검증"))) | K29: 최종 난이도·언어·접근성·세이브 이전·전체 회귀를 마무리한다. 리더보드·콘솔·추가 보이스는 별도 비용 대비 가치로 판단한다. | L29: 약속한 엔딩·콘텐츠가 완주 가능하고 EA 세이브 이전·지원 기기·언어별 핵심 흐름을 확인한다. 운영 및 수정 여유를 확보한다. | M29: 부가 기능을 미루고 제품 마무리에 집중한다. | N29: 기존 M4 QA·현지화·접근성·포팅 행
A30: PG5 | B30: 관문 | C30: v1.0 출시 결정 | D30: 2028 하반기 | E30: 2028 하반기 | F30: P19 | G30: 미착수 | H30: 미검증 | J30: =IF(G30="보류","보류",IF(H30="미달","보완 필요",IF(AND(G30="산출물 완료",H30="통과",I30<>""),IF(AND($J$29="통과"),"통과","선행 미통과"),"미검증"))) | K30: 기존 2028 Q4는 조건부 목표 창이다. 완성된 핵심 경험과 서사, 검증된 품질로 정식판을 판정한다. | L30: 공개한 약속 이행, 엔딩 회수, 치명 오류 미해결 0건, 지원 계획 확보를 사용자 확인한다. 150스킬·판매 2만 장을 제품 완성의 대리 지표로 삼지 않는다. | M30: 부가 콘텐츠를 연기하거나 출시 창을 조정한다. | N30: 기존 v1.0 출시 행 / 18 경쟁력 목표

Sheet Content Gantt
A1: 콘텐츠 항목 | B1: M1잔여 | C1: M2-Q1 | D1: M2-Q2 | E1: M3-Q3 | F1: M3-Q4 | G1: M3-Q5 | H1: M3-Q6 | I1: M4-Q7 | J1: M4-Q8 | K1: M4-Q9 | L1: M4-Q10 | M1: 작업자 | N1: 상태 | O1: 완료일시 | P1: 계획 종료일 | Q1: 진척 상태 | R1: 딜레이(일)
A2: (범례) | B2: 2026-06 | C2: 2026 Q3 | D2: 2026 Q4 | E2: 2027 Q1 | F2: 2027 Q2 | G2: 2027 Q3 EA 출시 | H2: 2027 Q4 | I2: 2028 Q1 | J2: 2028 Q2 | K2: 2028 Q3 | L2: 2028 Q4 v1.0 출시
A3: 폼 (Forms) — 10종 목표 ↗ (문서 열기)
A4: dark_blade — 암흑검사 (Warrior/fire) | B4: ✓ | M4: =_xlfn.XLOOKUP(A4,'작업관리'!B:B,'작업관리'!E:E,"") | N4: =_xlfn.XLOOKUP(A4,'작업관리'!B:B,'작업관리'!F:F,"") | O4: =_xlfn.XLOOKUP(A4,'작업관리'!B:B,'작업관리'!G:G,"") | P4: 46203 | Q4: =IF(N4="완료","완료",IF(N4="보류","보류",IF(N4="진행 중",IF(P4<TODAY(),"딜레이","진행중"),IF(P4<TODAY(),"딜레이",IF(TODAY()>=DATE(YEAR(P4),MONTH(P4)-2,1),"임박","예정"))))) | R4: =IF(OR(N4="완료",N4="보류"),"-",IF(P4<TODAY(),TODAY()-P4,""))
A5: void_archer — 공허궁수 (Archer/abyss) | B5: ✓ | M5: =_xlfn.XLOOKUP(A5,'작업관리'!B:B,'작업관리'!E:E,"") | N5: =_xlfn.XLOOKUP(A5,'작업관리'!B:B,'작업관리'!F:F,"") | O5: =_xlfn.XLOOKUP(A5,'작업관리'!B:B,'작업관리'!G:G,"") | P5: 46203 | Q5: =IF(N5="완료","완료",IF(N5="보류","보류",IF(N5="진행 중",IF(P5<TODAY(),"딜레이","진행중"),IF(P5<TODAY(),"딜레이",IF(TODAY()>=DATE(YEAR(P5),MONTH(P5)-2,1),"임박","예정"))))) | R5: =IF(OR(N5="완료",N5="보류"),"-",IF(P5<TODAY(),TODAY()-P5,""))
A6: ancient_shield — 고대 방패병 (Warrior/guard) | C6: ✓ | M6: =_xlfn.XLOOKUP(A6,'작업관리'!B:B,'작업관리'!E:E,"") | N6: =_xlfn.XLOOKUP(A6,'작업관리'!B:B,'작업관리'!F:F,"") | O6: =_xlfn.XLOOKUP(A6,'작업관리'!B:B,'작업관리'!G:G,"") | P6: 46295 | Q6: =IF(N6="완료","완료",IF(N6="보류","보류",IF(N6="진행 중",IF(P6<TODAY(),"딜레이","진행중"),IF(P6<TODAY(),"딜레이",IF(TODAY()>=DATE(YEAR(P6),MONTH(P6)-2,1),"임박","예정"))))) | R6: =IF(OR(N6="완료",N6="보류"),"-",IF(P6<TODAY(),TODAY()-P6,""))
A7: void_thrower — 심연 투척사 (Shifter/abyss) | D7: ✓ | M7: =_xlfn.XLOOKUP(A7,'작업관리'!B:B,'작업관리'!E:E,"") | N7: =_xlfn.XLOOKUP(A7,'작업관리'!B:B,'작업관리'!F:F,"") | O7: =_xlfn.XLOOKUP(A7,'작업관리'!B:B,'작업관리'!G:G,"") | P7: 46387 | Q7: =IF(N7="완료","완료",IF(N7="보류","보류",IF(N7="진행 중",IF(P7<TODAY(),"딜레이","진행중"),IF(P7<TODAY(),"딜레이",IF(TODAY()>=DATE(YEAR(P7),MONTH(P7)-2,1),"임박","예정"))))) | R7: =IF(OR(N7="완료",N7="보류"),"-",IF(P7<TODAY(),TODAY()-P7,""))
A8: frost_warden — 빙결 수호자 (Warrior/frost) | M8: =_xlfn.XLOOKUP(A8,'작업관리'!B:B,'작업관리'!E:E,"") | N8: =_xlfn.XLOOKUP(A8,'작업관리'!B:B,'작업관리'!F:F,"") | O8: =_xlfn.XLOOKUP(A8,'작업관리'!B:B,'작업관리'!G:G,"") | P8: 46477 | Q8: =IF(N8="완료","완료",IF(N8="보류","보류",IF(N8="진행 중",IF(P8<TODAY(),"딜레이","진행중"),IF(P8<TODAY(),"딜레이",IF(TODAY()>=DATE(YEAR(P8),MONTH(P8)-2,1),"임박","예정"))))) | R8: =IF(OR(N8="완료",N8="보류"),"-",IF(P8<TODAY(),TODAY()-P8,""))
A9: soul_dancer — 영혼 무희 (Shifter/abyss) | M9: =_xlfn.XLOOKUP(A9,'작업관리'!B:B,'작업관리'!E:E,"") | N9: =_xlfn.XLOOKUP(A9,'작업관리'!B:B,'작업관리'!F:F,"") | O9: =_xlfn.XLOOKUP(A9,'작업관리'!B:B,'작업관리'!G:G,"") | P9: 46568 | Q9: =IF(N9="완료","완료",IF(N9="보류","보류",IF(N9="진행 중",IF(P9<TODAY(),"딜레이","진행중"),IF(P9<TODAY(),"딜레이",IF(TODAY()>=DATE(YEAR(P9),MONTH(P9)-2,1),"임박","예정"))))) | R9: =IF(OR(N9="완료",N9="보류"),"-",IF(P9<TODAY(),TODAY()-P9,""))
A10: blood_reaver — 혈검 사신 (Warrior/blood_pact) | M10: =_xlfn.XLOOKUP(A10,'작업관리'!B:B,'작업관리'!E:E,"") | N10: =_xlfn.XLOOKUP(A10,'작업관리'!B:B,'작업관리'!F:F,"") | O10: =_xlfn.XLOOKUP(A10,'작업관리'!B:B,'작업관리'!G:G,"") | P10: 46843 | Q10: =IF(N10="완료","완료",IF(N10="보류","보류",IF(N10="진행 중",IF(P10<TODAY(),"딜레이","진행중"),IF(P10<TODAY(),"딜레이",IF(TODAY()>=DATE(YEAR(P10),MONTH(P10)-2,1),"임박","예정"))))) | R10: =IF(OR(N10="완료",N10="보류"),"-",IF(P10<TODAY(),TODAY()-P10,""))
A11: flame_oracle — 화염 신탁 (Archer/fire) | M11: =_xlfn.XLOOKUP(A11,'작업관리'!B:B,'작업관리'!E:E,"") | N11: =_xlfn.XLOOKUP(A11,'작업관리'!B:B,'작업관리'!F:F,"") | O11: =_xlfn.XLOOKUP(A11,'작업관리'!B:B,'작업관리'!G:G,"") | P11: 46934 | Q11: =IF(N11="완료","완료",IF(N11="보류","보류",IF(N11="진행 중",IF(P11<TODAY(),"딜레이","진행중"),IF(P11<TODAY(),"딜레이",IF(TODAY()>=DATE(YEAR(P11),MONTH(P11)-2,1),"임박","예정"))))) | R11: =IF(OR(N11="완료",N11="보류"),"-",IF(P11<TODAY(),TODAY()-P11,""))
A12: soul_binder — 영혼 결속자 (Shifter/soul) | M12: =_xlfn.XLOOKUP(A12,'작업관리'!B:B,'작업관리'!E:E,"") | N12: =_xlfn.XLOOKUP(A12,'작업관리'!B:B,'작업관리'!F:F,"") | O12: =_xlfn.XLOOKUP(A12,'작업관리'!B:B,'작업관리'!G:G,"") | P12: 47026 | Q12: =IF(N12="완료","완료",IF(N12="보류","보류",IF(N12="진행 중",IF(P12<TODAY(),"딜레이","진행중"),IF(P12<TODAY(),"딜레이",IF(TODAY()>=DATE(YEAR(P12),MONTH(P12)-2,1),"임박","예정"))))) | R12: =IF(OR(N12="완료",N12="보류"),"-",IF(P12<TODAY(),TODAY()-P12,""))
A13: abyss_avatar — 심연의 화신 [히든] | L13: H | M13: =_xlfn.XLOOKUP(A13,'작업관리'!B:B,'작업관리'!E:E,"") | N13: =_xlfn.XLOOKUP(A13,'작업관리'!B:B,'작업관리'!F:F,"") | O13: =_xlfn.XLOOKUP(A13,'작업관리'!B:B,'작업관리'!G:G,"") | P13: 47118 | Q13: =IF(N13="완료","완료",IF(N13="보류","보류",IF(N13="진행 중",IF(P13<TODAY(),"딜레이","진행중"),IF(P13<TODAY(),"딜레이",IF(TODAY()>=DATE(YEAR(P13),MONTH(P13)-2,1),"임박","예정"))))) | R13: =IF(OR(N13="완료",N13="보류"),"-",IF(P13<TODAY(),TODAY()-P13,""))
A14: 시너지 축 (Synergy Axes) — 6축 ↗ (문서 열기)
A15: fire — 불꽃 (DoT·폭발) | B15: ✓ | M15: =_xlfn.XLOOKUP(A15,'작업관리'!B:B,'작업관리'!E:E,"") | N15: =_xlfn.XLOOKUP(A15,'작업관리'!B:B,'작업관리'!F:F,"") | O15: =_xlfn.XLOOKUP(A15,'작업관리'!B:B,'작업관리'!G:G,"") | P15: 46203 | Q15: =IF(N15="완료","완료",IF(N15="보류","보류",IF(N15="진행 중",IF(P15<TODAY(),"딜레이","진행중"),IF(P15<TODAY(),"딜레이",IF(TODAY()>=DATE(YEAR(P15),MONTH(P15)-2,1),"임박","예정"))))) | R15: =IF(OR(N15="완료",N15="보류"),"-",IF(P15<TODAY(),TODAY()-P15,""))
A16: abyss — 심연 (이동·대시·잔상) | B16: ✓ | M16: =_xlfn.XLOOKUP(A16,'작업관리'!B:B,'작업관리'!E:E,"") | N16: =_xlfn.XLOOKUP(A16,'작업관리'!B:B,'작업관리'!F:F,"") | O16: =_xlfn.XLOOKUP(A16,'작업관리'!B:B,'작업관리'!G:G,"") | P16: 46203 | Q16: =IF(N16="완료","완료",IF(N16="보류","보류",IF(N16="진행 중",IF(P16<TODAY(),"딜레이","진행중"),IF(P16<TODAY(),"딜레이",IF(TODAY()>=DATE(YEAR(P16),MONTH(P16)-2,1),"임박","예정"))))) | R16: =IF(OR(N16="완료",N16="보류"),"-",IF(P16<TODAY(),TODAY()-P16,""))
A17: guard — 수호 (방어·가드 카운터) | C17: ✓ | M17: =_xlfn.XLOOKUP(A17,'작업관리'!B:B,'작업관리'!E:E,"") | N17: =_xlfn.XLOOKUP(A17,'작업관리'!B:B,'작업관리'!F:F,"") | O17: =_xlfn.XLOOKUP(A17,'작업관리'!B:B,'작업관리'!G:G,"") | P17: 46295 | Q17: =IF(N17="완료","완료",IF(N17="보류","보류",IF(N17="진행 중",IF(P17<TODAY(),"딜레이","진행중"),IF(P17<TODAY(),"딜레이",IF(TODAY()>=DATE(YEAR(P17),MONTH(P17)-2,1),"임박","예정"))))) | R17: =IF(OR(N17="완료",N17="보류"),"-",IF(P17<TODAY(),TODAY()-P17,""))
A18: 시너지 발동 로직 (폭발 신학·심연 동료) | D18: ✓ | M18: =_xlfn.XLOOKUP(A18,'작업관리'!B:B,'작업관리'!E:E,"") | N18: =_xlfn.XLOOKUP(A18,'작업관리'!B:B,'작업관리'!F:F,"") | O18: =_xlfn.XLOOKUP(A18,'작업관리'!B:B,'작업관리'!G:G,"") | P18: 46387 | Q18: =IF(N18="완료","완료",IF(N18="보류","보류",IF(N18="진행 중",IF(P18<TODAY(),"딜레이","진행중"),IF(P18<TODAY(),"딜레이",IF(TODAY()>=DATE(YEAR(P18),MONTH(P18)-2,1),"임박","예정"))))) | R18: =IF(OR(N18="완료",N18="보류"),"-",IF(P18<TODAY(),TODAY()-P18,""))
A19: 연소 상태이상 (불꽃 축 기반 DoT) | D19: ✓ | M19: =_xlfn.XLOOKUP(A19,'작업관리'!B:B,'작업관리'!E:E,"") | N19: =_xlfn.XLOOKUP(A19,'작업관리'!B:B,'작업관리'!F:F,"") | O19: =_xlfn.XLOOKUP(A19,'작업관리'!B:B,'작업관리'!G:G,"") | P19: 46387 | Q19: =IF(N19="완료","완료",IF(N19="보류","보류",IF(N19="진행 중",IF(P19<TODAY(),"딜레이","진행중"),IF(P19<TODAY(),"딜레이",IF(TODAY()>=DATE(YEAR(P19),MONTH(P19)-2,1),"임박","예정"))))) | R19: =IF(OR(N19="완료",N19="보류"),"-",IF(P19<TODAY(),TODAY()-P19,""))
A20: Passive 발동 로직 (연소 강화·불꽃 갑옷) | D20: ✓ | M20: =_xlfn.XLOOKUP(A20,'작업관리'!B:B,'작업관리'!E:E,"") | N20: =_xlfn.XLOOKUP(A20,'작업관리'!B:B,'작업관리'!F:F,"") | O20: =_xlfn.XLOOKUP(A20,'작업관리'!B:B,'작업관리'!G:G,"") | P20: 46387 | Q20: =IF(N20="완료","완료",IF(N20="보류","보류",IF(N20="진행 중",IF(P20<TODAY(),"딜레이","진행중"),IF(P20<TODAY(),"딜레이",IF(TODAY()>=DATE(YEAR(P20),MONTH(P20)-2,1),"임박","예정"))))) | R20: =IF(OR(N20="완료",N20="보류"),"-",IF(P20<TODAY(),TODAY()-P20,""))
A21: Passive 발동 로직 (잔상·심연 충전) | D21: ✓ | M21: =_xlfn.XLOOKUP(A21,'작업관리'!B:B,'작업관리'!E:E,"") | N21: =_xlfn.XLOOKUP(A21,'작업관리'!B:B,'작업관리'!F:F,"") | O21: =_xlfn.XLOOKUP(A21,'작업관리'!B:B,'작업관리'!G:G,"") | P21: 46387 | Q21: =IF(N21="완료","완료",IF(N21="보류","보류",IF(N21="진행 중",IF(P21<TODAY(),"딜레이","진행중"),IF(P21<TODAY(),"딜레이",IF(TODAY()>=DATE(YEAR(P21),MONTH(P21)-2,1),"임박","예정"))))) | R21: =IF(OR(N21="완료",N21="보류"),"-",IF(P21<TODAY(),TODAY()-P21,""))
A22: blood_pact — 피의 서약 (흡혈) | I22: ✓ | M22: =_xlfn.XLOOKUP(A22,'작업관리'!B:B,'작업관리'!E:E,"") | N22: =_xlfn.XLOOKUP(A22,'작업관리'!B:B,'작업관리'!F:F,"") | O22: =_xlfn.XLOOKUP(A22,'작업관리'!B:B,'작업관리'!G:G,"") | P22: 46843 | Q22: =IF(N22="완료","완료",IF(N22="보류","보류",IF(N22="진행 중",IF(P22<TODAY(),"딜레이","진행중"),IF(P22<TODAY(),"딜레이",IF(TODAY()>=DATE(YEAR(P22),MONTH(P22)-2,1),"임박","예정"))))) | R22: =IF(OR(N22="완료",N22="보류"),"-",IF(P22<TODAY(),TODAY()-P22,""))
A23: frost — 빙결 (CC 누적) | M23: =_xlfn.XLOOKUP(A23,'작업관리'!B:B,'작업관리'!E:E,"") | N23: =_xlfn.XLOOKUP(A23,'작업관리'!B:B,'작업관리'!F:F,"") | O23: =_xlfn.XLOOKUP(A23,'작업관리'!B:B,'작업관리'!G:G,"") | P23: 46477 | Q23: =IF(N23="완료","완료",IF(N23="보류","보류",IF(N23="진행 중",IF(P23<TODAY(),"딜레이","진행중"),IF(P23<TODAY(),"딜레이",IF(TODAY()>=DATE(YEAR(P23),MONTH(P23)-2,1),"임박","예정"))))) | R23: =IF(OR(N23="완료",N23="보류"),"-",IF(P23<TODAY(),TODAY()-P23,""))
A24: soul — 영혼 (복제·능력 차용) | M24: =_xlfn.XLOOKUP(A24,'작업관리'!B:B,'작업관리'!E:E,"") | N24: =_xlfn.XLOOKUP(A24,'작업관리'!B:B,'작업관리'!F:F,"") | O24: =_xlfn.XLOOKUP(A24,'작업관리'!B:B,'작업관리'!G:G,"") | P24: 47026 | Q24: =IF(N24="완료","완료",IF(N24="보류","보류",IF(N24="진행 중",IF(P24<TODAY(),"딜레이","진행중"),IF(P24<TODAY(),"딜레이",IF(TODAY()>=DATE(YEAR(P24),MONTH(P24)-2,1),"임박","예정"))))) | R24: =IF(OR(N24="완료",N24="보류"),"-",IF(P24<TODAY(),TODAY()-P24,""))
A25: 스킬 풀 (Skills) — 150개 목표 ↗ (문서 열기)
A26: 11 스킬 (불꽃 5 + 심연 5 + 버프 1) | B26: 11 | M26: =_xlfn.XLOOKUP(A26,'작업관리'!B:B,'작업관리'!E:E,"") | N26: =_xlfn.XLOOKUP(A26,'작업관리'!B:B,'작업관리'!F:F,"") | O26: =_xlfn.XLOOKUP(A26,'작업관리'!B:B,'작업관리'!G:G,"") | P26: 46203 | Q26: =IF(N26="완료","완료",IF(N26="보류","보류",IF(N26="진행 중",IF(P26<TODAY(),"딜레이","진행중"),IF(P26<TODAY(),"딜레이",IF(TODAY()>=DATE(YEAR(P26),MONTH(P26)-2,1),"임박","예정"))))) | R26: =IF(OR(N26="완료",N26="보류"),"-",IF(P26<TODAY(),TODAY()-P26,""))
A27: 18 스킬 (+화염 폭발·영혼 회수·반격 태세) | C27: ✓ | M27: =_xlfn.XLOOKUP(A27,'작업관리'!B:B,'작업관리'!E:E,"") | N27: =_xlfn.XLOOKUP(A27,'작업관리'!B:B,'작업관리'!F:F,"") | O27: =_xlfn.XLOOKUP(A27,'작업관리'!B:B,'작업관리'!G:G,"") | P27: 46295 | Q27: =IF(N27="완료","완료",IF(N27="보류","보류",IF(N27="진행 중",IF(P27<TODAY(),"딜레이","진행중"),IF(P27<TODAY(),"딜레이",IF(TODAY()>=DATE(YEAR(P27),MONTH(P27)-2,1),"임박","예정"))))) | R27: =IF(OR(N27="완료",N27="보류"),"-",IF(P27<TODAY(),TODAY()-P27,""))
A28: 기존 18스킬의 3빌드 검증 후 30~40종 검토 (피의 서약은 M4) | D28: 30종 사용자 검증·커밋 da8e6e0 · 액티브 아이콘 2종 Codex 대기 (2026-10-06) | M28: =_xlfn.XLOOKUP(A28,'작업관리'!B:B,'작업관리'!E:E,"") | N28: =_xlfn.XLOOKUP(A28,'작업관리'!B:B,'작업관리'!F:F,"") | O28: =_xlfn.XLOOKUP(A28,'작업관리'!B:B,'작업관리'!G:G,"") | P28: 46387 | Q28: =IF(N28="완료","완료",IF(N28="보류","보류",IF(N28="진행 중",IF(P28<TODAY(),"딜레이","진행중"),IF(P28<TODAY(),"딜레이",IF(TODAY()>=DATE(YEAR(P28),MONTH(P28)-2,1),"임박","예정"))))) | R28: =IF(OR(N28="완료",N28="보류"),"-",IF(P28<TODAY(),TODAY()-P28,""))
A29: 60스킬 확장 후보 (PG2 후 · 빙결은 폼 제작과 연동) | E29: 60 | M29: =_xlfn.XLOOKUP(A29,'작업관리'!B:B,'작업관리'!E:E,"") | N29: =_xlfn.XLOOKUP(A29,'작업관리'!B:B,'작업관리'!F:F,"") | O29: =_xlfn.XLOOKUP(A29,'작업관리'!B:B,'작업관리'!G:G,"") | P29: 46477 | Q29: =IF(N29="완료","완료",IF(N29="보류","보류",IF(N29="진행 중",IF(P29<TODAY(),"딜레이","진행중"),IF(P29<TODAY(),"딜레이",IF(TODAY()>=DATE(YEAR(P29),MONTH(P29)-2,1),"임박","예정"))))) | R29: =IF(OR(N29="완료",N29="보류"),"-",IF(P29<TODAY(),TODAY()-P29,""))
A30: EA 스킬 풀 확정 (80종 후보 · PG2 제작성에 따라 조정) | F30: 80 | M30: =_xlfn.XLOOKUP(A30,'작업관리'!B:B,'작업관리'!E:E,"") | N30: =_xlfn.XLOOKUP(A30,'작업관리'!B:B,'작업관리'!F:F,"") | O30: =_xlfn.XLOOKUP(A30,'작업관리'!B:B,'작업관리'!G:G,"") | P30: 46568 | Q30: =IF(N30="완료","완료",IF(N30="보류","보류",IF(N30="진행 중",IF(P30<TODAY(),"딜레이","진행중"),IF(P30<TODAY(),"딜레이",IF(TODAY()>=DATE(YEAR(P30),MONTH(P30)-2,1),"임박","예정"))))) | R30: =IF(OR(N30="완료",N30="보류"),"-",IF(P30<TODAY(),TODAY()-P30,""))
A31: EA 운영 스킬 확장 (100종 후보 · 실제 피드백 우선) | G31: 90→100 | H31: 90→100 | M31: =_xlfn.XLOOKUP(A31,'작업관리'!B:B,'작업관리'!E:E,"") | N31: =_xlfn.XLOOKUP(A31,'작업관리'!B:B,'작업관리'!F:F,"") | O31: =_xlfn.XLOOKUP(A31,'작업관리'!B:B,'작업관리'!G:G,"") | P31: 46752 | Q31: =IF(N31="완료","완료",IF(N31="보류","보류",IF(N31="진행 중",IF(P31<TODAY(),"딜레이","진행중"),IF(P31<TODAY(),"딜레이",IF(TODAY()>=DATE(YEAR(P31),MONTH(P31)-2,1),"임박","예정"))))) | R31: =IF(OR(N31="완료",N31="보류"),"-",IF(P31<TODAY(),TODAY()-P31,""))
A32: 후반 스킬 확장 (130종 후보 · 영혼 축 가치 검증) | I32: 110→130 | J32: 110→130 | K32: 110→130 | M32: =_xlfn.XLOOKUP(A32,'작업관리'!B:B,'작업관리'!E:E,"") | N32: =_xlfn.XLOOKUP(A32,'작업관리'!B:B,'작업관리'!F:F,"") | O32: =_xlfn.XLOOKUP(A32,'작업관리'!B:B,'작업관리'!G:G,"") | P32: 47026 | Q32: =IF(N32="완료","완료",IF(N32="보류","보류",IF(N32="진행 중",IF(P32<TODAY(),"딜레이","진행중"),IF(P32<TODAY(),"딜레이",IF(TODAY()>=DATE(YEAR(P32),MONTH(P32)-2,1),"임박","예정"))))) | R32: =IF(OR(N32="완료",N32="보류"),"-",IF(P32<TODAY(),TODAY()-P32,""))
A33: 정식판 스킬 풀 마무리 (150종 상한 후보 · 개수 강제 없음) | L33: 150 | M33: =_xlfn.XLOOKUP(A33,'작업관리'!B:B,'작업관리'!E:E,"") | N33: =_xlfn.XLOOKUP(A33,'작업관리'!B:B,'작업관리'!F:F,"") | O33: =_xlfn.XLOOKUP(A33,'작업관리'!B:B,'작업관리'!G:G,"") | P33: 47118 | Q33: =IF(N33="완료","완료",IF(N33="보류","보류",IF(N33="진행 중",IF(P33<TODAY(),"딜레이","진행중"),IF(P33<TODAY(),"딜레이",IF(TODAY()>=DATE(YEAR(P33),MONTH(P33)-2,1),"임박","예정"))))) | R33: =IF(OR(N33="완료",N33="보류"),"-",IF(P33<TODAY(),TODAY()-P33,""))
A34: 적 (Enemies) — 40~50종 목표 ↗ (문서 열기)
A35: 일반 적 5종 (Melee×2 / Ranged / Elite / Boss) | B35: ✓ | M35: =_xlfn.XLOOKUP(A35,'작업관리'!B:B,'작업관리'!E:E,"") | N35: =_xlfn.XLOOKUP(A35,'작업관리'!B:B,'작업관리'!F:F,"") | O35: =_xlfn.XLOOKUP(A35,'작업관리'!B:B,'작업관리'!G:G,"") | P35: 46203 | Q35: =IF(N35="완료","완료",IF(N35="보류","보류",IF(N35="진행 중",IF(P35<TODAY(),"딜레이","진행중"),IF(P35<TODAY(),"딜레이",IF(TODAY()>=DATE(YEAR(P35),MONTH(P35)-2,1),"임박","예정"))))) | R35: =IF(OR(N35="완료",N35="보류"),"-",IF(P35<TODAY(),TODAY()-P35,""))
A36: 발사체 시스템 + 원거리적 정상화 | C36: ✓ | M36: =_xlfn.XLOOKUP(A36,'작업관리'!B:B,'작업관리'!E:E,"") | N36: =_xlfn.XLOOKUP(A36,'작업관리'!B:B,'작업관리'!F:F,"") | O36: =_xlfn.XLOOKUP(A36,'작업관리'!B:B,'작업관리'!G:G,"") | P36: 46295 | Q36: =IF(N36="완료","완료",IF(N36="보류","보류",IF(N36="진행 중",IF(P36<TODAY(),"딜레이","진행중"),IF(P36<TODAY(),"딜레이",IF(TODAY()>=DATE(YEAR(P36),MONTH(P36)-2,1),"임박","예정"))))) | R36: =IF(OR(N36="완료",N36="보류"),"-",IF(P36<TODAY(),TODAY()-P36,""))
A37: 원거리·발사체형 3종 신규 | C37: ✓ | M37: =_xlfn.XLOOKUP(A37,'작업관리'!B:B,'작업관리'!E:E,"") | N37: =_xlfn.XLOOKUP(A37,'작업관리'!B:B,'작업관리'!F:F,"") | O37: =_xlfn.XLOOKUP(A37,'작업관리'!B:B,'작업관리'!G:G,"") | P37: 46295 | Q37: =IF(N37="완료","완료",IF(N37="보류","보류",IF(N37="진행 중",IF(P37<TODAY(),"딜레이","진행중"),IF(P37<TODAY(),"딜레이",IF(TODAY()>=DATE(YEAR(P37),MONTH(P37)-2,1),"임박","예정"))))) | R37: =IF(OR(N37="완료",N37="보류"),"-",IF(P37<TODAY(),TODAY()-P37,""))
A38: 환경 활용형 (천장·잠복·부유) 3종 | M38: =_xlfn.XLOOKUP(A38,'작업관리'!B:B,'작업관리'!E:E,"") | N38: =_xlfn.XLOOKUP(A38,'작업관리'!B:B,'작업관리'!F:F,"") | O38: =_xlfn.XLOOKUP(A38,'작업관리'!B:B,'작업관리'!G:G,"") | P38: 46387 | Q38: =IF(N38="완료","완료",IF(N38="보류","보류",IF(N38="진행 중",IF(P38<TODAY(),"딜레이","진행중"),IF(P38<TODAY(),"딜레이",IF(TODAY()>=DATE(YEAR(P38),MONTH(P38)-2,1),"임박","예정"))))) | R38: =IF(OR(N38="완료",N38="보류"),"-",IF(P38<TODAY(),TODAY()-P38,""))
A39: 엘리트 변종 2종 (광폭화·소환사) | D39: ✓ | M39: =_xlfn.XLOOKUP(A39,'작업관리'!B:B,'작업관리'!E:E,"") | N39: =_xlfn.XLOOKUP(A39,'작업관리'!B:B,'작업관리'!F:F,"") | O39: =_xlfn.XLOOKUP(A39,'작업관리'!B:B,'작업관리'!G:G,"") | P39: 46387 | Q39: =IF(N39="완료","완료",IF(N39="보류","보류",IF(N39="진행 중",IF(P39<TODAY(),"딜레이","진행중"),IF(P39<TODAY(),"딜레이",IF(TODAY()>=DATE(YEAR(P39),MONTH(P39)-2,1),"임박","예정"))))) | R39: =IF(OR(N39="완료",N39="보류"),"-",IF(P39<TODAY(),TODAY()-P39,""))
A40: 스테이지 4~5 신규 적 풀 (각 6~7종) | M40: =_xlfn.XLOOKUP(A40,'작업관리'!B:B,'작업관리'!E:E,"") | N40: =_xlfn.XLOOKUP(A40,'작업관리'!B:B,'작업관리'!F:F,"") | O40: =_xlfn.XLOOKUP(A40,'작업관리'!B:B,'작업관리'!G:G,"") | P40: 46568 | Q40: =IF(N40="완료","완료",IF(N40="보류","보류",IF(N40="진행 중",IF(P40<TODAY(),"딜레이","진행중"),IF(P40<TODAY(),"딜레이",IF(TODAY()>=DATE(YEAR(P40),MONTH(P40)-2,1),"임박","예정"))))) | R40: =IF(OR(N40="완료",N40="보류"),"-",IF(P40<TODAY(),TODAY()-P40,""))
...

Sheet 작업관리
A1: 사용법: E열에 작업자 입력 / F열 드롭다운에서 상태 선택 / 완료 시 G열에 Ctrl+; (오늘 날짜 정적 입력) → Content Gantt 시트에 자동 반영
A2: 콘텐츠 ID | B2: 콘텐츠명 | C2: 카테고리 | D2: 계획 분기 | E2: 작업자 | F2: 상태 | G2: 완료일시 | H2: 비고
A3: F-01 | B3: dark_blade — 암흑검사 (Warrior/fire) | C3: 폼 (Forms) — 10종 목표 | D3: M1잔여 | F3: 완료 | H3: M1완료
A4: F-02 | B4: void_archer — 공허궁수 (Archer/abyss) | C4: 폼 (Forms) — 10종 목표 | D4: M1잔여 | F4: 완료 | H4: M1완료
A5: F-03 | B5: ancient_shield — 고대 방패병 (Warrior/guard) | C5: 폼 (Forms) — 10종 목표 | D5: M2-Q1 | F5: 완료 | H5: M1완료
A6: F-04 | B6: void_thrower — 심연 투척사 (Shifter/abyss) | C6: 폼 (Forms) — 10종 목표 | D6: M2-Q2 | F6: 완료 | H6: M1완료
A7: F-05 | B7: frost_warden — 빙결 수호자 (Warrior/frost) | C7: 폼 (Forms) — 10종 목표 | D7: M3-Q3 | F7: 대기
A8: F-06 | B8: soul_dancer — 영혼 무희 (Shifter/abyss) | C8: 폼 (Forms) — 10종 목표 | D8: M3-Q4 | F8: 대기
A9: F-07 | B9: blood_reaver — 혈검 사신 (Warrior/blood_pact) | C9: 폼 (Forms) — 10종 목표 | D9: M4-Q7 | F9: 대기
A10: F-08 | B10: flame_oracle — 화염 신탁 (Archer/fire) | C10: 폼 (Forms) — 10종 목표 | D10: M4-Q8 | F10: 대기
A11: F-09 | B11: soul_binder — 영혼 결속자 (Shifter/soul) | C11: 폼 (Forms) — 10종 목표 | D11: M4-Q9 | F11: 대기
A12: F-10 | B12: abyss_avatar — 심연의 화신 [히든] | C12: 폼 (Forms) — 10종 목표 | D12: M4-Q10 | F12: 대기 | H12: 히든
A13: A-01 | B13: fire — 불꽃 (DoT·폭발) | C13: 시너지 축 (Synergy Axes) — 6축 | D13: M1잔여 | F13: 완료 | H13: M1완료
A14: A-02 | B14: abyss — 심연 (이동·대시·잔상) | C14: 시너지 축 (Synergy Axes) — 6축 | D14: M1잔여 | F14: 완료 | H14: M1완료
A15: A-03 | B15: guard — 수호 (방어·가드 카운터) | C15: 시너지 축 (Synergy Axes) — 6축 | D15: M2-Q1 | F15: 완료 | H15: M1완료
A16: A-04 | B16: 시너지 발동 로직 (폭발 신학·심연 동료) | C16: 시너지 축 (Synergy Axes) — 6축 | D16: M2-Q2 | F16: 완료 | H16: M1완료
A17: A-05 | B17: 연소 상태이상 (불꽃 축 기반 DoT) | C17: 시너지 축 (Synergy Axes) — 6축 | D17: M2-Q2 | F17: 완료 | H17: M1완료
A18: A-06 | B18: Passive 발동 로직 (연소 강화·불꽃 갑옷) | C18: 시너지 축 (Synergy Axes) — 6축 | D18: M2-Q2 | F18: 완료 | H18: M1완료
A19: A-07 | B19: Passive 발동 로직 (잔상·심연 충전) | C19: 시너지 축 (Synergy Axes) — 6축 | D19: M2-Q2 | F19: 완료 | H19: M1완료
A20: A-08 | B20: blood_pact — 피의 서약 (흡혈) | C20: 시너지 축 (Synergy Axes) — 6축 | D20: M4-Q7 | F20: 대기
A21: A-09 | B21: frost — 빙결 (CC 누적) | C21: 시너지 축 (Synergy Axes) — 6축 | D21: M3-Q3 | F21: 대기
A22: A-10 | B22: soul — 영혼 (복제·능력 차용) | C22: 시너지 축 (Synergy Axes) — 6축 | D22: M4-Q9 | F22: 대기
A23: K-01 | B23: 11 스킬 (불꽃 5 + 심연 5 + 버프 1) | C23: 스킬 풀 (Skills) — 150개 목표 | D23: M1잔여 | F23: 대기 | H23: 11
A24: K-02 | B24: 18 스킬 (+화염 폭발·영혼 회수·반격 태세) | C24: 스킬 풀 (Skills) — 150개 목표 | D24: M2-Q1 | F24: 완료 | H24: M1완료
A25: K-03 | B25: 기존 18스킬의 3빌드 검증 후 30~40종 검토 (피의 서약은 M4) | C25: 스킬 풀 (Skills) — 150개 목표 | D25: M2-Q2 | F25: 대기 | H25: 30~40
A26: K-04 | B26: 60스킬 확장 후보 (PG2 후 · 빙결은 폼 제작과 연동) | C26: 스킬 풀 (Skills) — 150개 목표 | D26: M3-Q3 | F26: 대기 | H26: 60
A27: K-05 | B27: EA 스킬 풀 확정 (80종 후보 · PG2 제작성에 따라 조정) | C27: 스킬 풀 (Skills) — 150개 목표 | D27: M3-Q4 | F27: 대기 | H27: 80
A28: K-06 | B28: EA 운영 스킬 확장 (100종 후보 · 실제 피드백 우선) | C28: 스킬 풀 (Skills) — 150개 목표 | D28: M3-Q5~M3-Q6 | F28: 대기 | H28: 90→100
A29: K-07 | B29: 후반 스킬 확장 (130종 후보 · 영혼 축 가치 검증) | C29: 스킬 풀 (Skills) — 150개 목표 | D29: M4-Q7~M4-Q9 | F29: 대기 | H29: 110→130
A30: K-08 | B30: 정식판 스킬 풀 마무리 (150종 상한 후보 · 개수 강제 없음) | C30: 스킬 풀 (Skills) — 150개 목표 | D30: M4-Q10 | F30: 대기 | H30: 150
A31: E-01 | B31: 일반 적 5종 (Melee×2 / Ranged / Elite / Boss) | C31: 적 (Enemies) — 40~50종 목표 | D31: M1잔여 | F31: 완료 | H31: M1완료
A32: E-02 | B32: 발사체 시스템 + 원거리적 정상화 | C32: 적 (Enemies) — 40~50종 목표 | D32: M2-Q1 | F32: 완료 | H32: M1완료
A33: E-03 | B33: 원거리·발사체형 3종 신규 | C33: 적 (Enemies) — 40~50종 목표 | D33: M2-Q1 | F33: 완료 | H33: M1완료
A34: E-04 | B34: 환경 활용형 (천장·잠복·부유) 3종 | C34: 적 (Enemies) — 40~50종 목표 | D34: M2-Q2 | F34: 대기
A35: E-05 | B35: 엘리트 변종 2종 (광폭화·소환사) | C35: 적 (Enemies) — 40~50종 목표 | D35: M2-Q2 | F35: 대기
A36: E-06 | B36: 스테이지 4~5 신규 적 풀 (각 6~7종) | C36: 적 (Enemies) — 40~50종 목표 | D36: M3-Q3~M3-Q4 | F36: 대기
A37: E-07 | B37: 환경 트랩 NPC (터렛·낙석) | C37: 적 (Enemies) — 40~50종 목표 | D37: M3-Q4 | F37: 대기
A38: E-08 | B38: 히든·도전 모드 적 5~7종 | C38: 적 (Enemies) — 40~50종 목표 | D38: M4-Q10 | F38: 대기 | H38: 히든
A39: B-01 | B39: 보스 페이즈 탄막 패턴 (부채꼴 볼리, 공통) | C39: 보스 (Bosses) — 10~12종 목표 | D39: M1잔여 | F39: 완료 | H39: M1완료
A40: B-02 | B40: 보스 고유 패턴 (회전베기/화염브레스/꼬리치기) | C40: 보스 (Bosses) — 10~12종 목표 | D40: M2-Q1 | F40: 완료 | H40: M1완료
...

Sheet 진척 대시보드
A1: Abyss 기존 제작 목록 진척 (재미·출시 준비율 아님)
A3: 오늘 | B3: =TODAY()
A4: 총 콘텐츠 수 | B4: 263
A6: 상태 | B6: 개수 | C6: 비율 | E6: 추가 상태 | F6: 개수 | G6: 비율
A7: 완료 | B7: =COUNTIF('작업관리'!F:F,"완료") | C7: =B7/$B$4 | E7: 설계 완료 | F7: =COUNTIFS('작업관리'!$F$3:$F$265,E7) | G7: =F7/$B$4
A8: 진행 중 | B8: =COUNTIF('작업관리'!F:F,"진행 중") | C8: =B8/$B$4 | E8: 보류 | F8: =COUNTIFS('작업관리'!$F$3:$F$265,E8) | G8: =F8/$B$4
A9: 대기 | B9: =COUNTIF('작업관리'!F:F,"대기") | C9: =B9/$B$4
A10: 딜레이 | B10: =COUNTIF('Content Gantt'!Q:Q,"딜레이") | C10: =B10/$B$4 | E10: 딜레이는 상태와 중복 집계
A12: 카테고리 | B12: 총 | C12: 완료 | D12: 진행 중 | E12: 대기·설계·보류 | F12: 딜레이 | G12: 진척률
A13: 폼 (Forms) — 10종 목표 | B13: =COUNTIFS('작업관리'!$C$3:$C$265,A13) | C13: =COUNTIFS('작업관리'!$C$3:$C$265,A13,'작업관리'!$F$3:$F$265,"완료") | D13: =COUNTIFS('작업관리'!$C$3:$C$265,A13,'작업관리'!$F$3:$F$265,"진행 중") | E13: =B13-C13-D13 | F13: - | G13: =IF(B13=0,"",C13/B13)
A14: 시너지 축 (Synergy Axes) — 6축 | B14: =COUNTIFS('작업관리'!$C$3:$C$265,A14) | C14: =COUNTIFS('작업관리'!$C$3:$C$265,A14,'작업관리'!$F$3:$F$265,"완료") | D14: =COUNTIFS('작업관리'!$C$3:$C$265,A14,'작업관리'!$F$3:$F$265,"진행 중") | E14: =B14-C14-D14 | F14: - | G14: =IF(B14=0,"",C14/B14)
A15: 스킬 풀 (Skills) — 150개 목표 | B15: =COUNTIFS('작업관리'!$C$3:$C$265,A15) | C15: =COUNTIFS('작업관리'!$C$3:$C$265,A15,'작업관리'!$F$3:$F$265,"완료") | D15: =COUNTIFS('작업관리'!$C$3:$C$265,A15,'작업관리'!$F$3:$F$265,"진행 중") | E15: =B15-C15-D15 | F15: - | G15: =IF(B15=0,"",C15/B15)
A16: 적 (Enemies) — 40~50종 목표 | B16: =COUNTIFS('작업관리'!$C$3:$C$265,A16) | C16: =COUNTIFS('작업관리'!$C$3:$C$265,A16,'작업관리'!$F$3:$F$265,"완료") | D16: =COUNTIFS('작업관리'!$C$3:$C$265,A16,'작업관리'!$F$3:$F$265,"진행 중") | E16: =B16-C16-D16 | F16: - | G16: =IF(B16=0,"",C16/B16)
A17: 보스 (Bosses) — 10~12종 목표 | B17: =COUNTIFS('작업관리'!$C$3:$C$265,A17) | C17: =COUNTIFS('작업관리'!$C$3:$C$265,A17,'작업관리'!$F$3:$F$265,"완료") | D17: =COUNTIFS('작업관리'!$C$3:$C$265,A17,'작업관리'!$F$3:$F$265,"진행 중") | E17: =B17-C17-D17 | F17: - | G17: =IF(B17=0,"",C17/B17)
A18: 스테이지·방 타입 (Stages & Rooms) | B18: =COUNTIFS('작업관리'!$C$3:$C$265,A18) | C18: =COUNTIFS('작업관리'!$C$3:$C$265,A18,'작업관리'!$F$3:$F$265,"완료") | D18: =COUNTIFS('작업관리'!$C$3:$C$265,A18,'작업관리'!$F$3:$F$265,"진행 중") | E18: =B18-C18-D18 | F18: - | G18: =IF(B18=0,"",C18/B18)
A19: 메타 진행 (Meta Progression) | B19: =COUNTIFS('작업관리'!$C$3:$C$265,A19) | C19: =COUNTIFS('작업관리'!$C$3:$C$265,A19,'작업관리'!$F$3:$F$265,"완료") | D19: =COUNTIFS('작업관리'!$C$3:$C$265,A19,'작업관리'!$F$3:$F$265,"진행 중") | E19: =B19-C19-D19 | F19: - | G19: =IF(B19=0,"",C19/B19)
A20: 스토리·서사 (Story & Narrative) | B20: =COUNTIFS('작업관리'!$C$3:$C$265,A20) | C20: =COUNTIFS('작업관리'!$C$3:$C$265,A20,'작업관리'!$F$3:$F$265,"완료") | D20: =COUNTIFS('작업관리'!$C$3:$C$265,A20,'작업관리'!$F$3:$F$265,"진행 중") | E20: =B20-C20-D20 | F20: - | G20: =IF(B20=0,"",C20/B20)
A21: 사운드 (Audio) | B21: =COUNTIFS('작업관리'!$C$3:$C$265,A21) | C21: =COUNTIFS('작업관리'!$C$3:$C$265,A21,'작업관리'!$F$3:$F$265,"완료") | D21: =COUNTIFS('작업관리'!$C$3:$C$265,A21,'작업관리'!$F$3:$F$265,"진행 중") | E21: =B21-C21-D21 | F21: - | G21: =IF(B21=0,"",C21/B21)
A22: UI·메뉴 (UI / Menus) | B22: =COUNTIFS('작업관리'!$C$3:$C$265,A22) | C22: =COUNTIFS('작업관리'!$C$3:$C$265,A22,'작업관리'!$F$3:$F$265,"완료") | D22: =COUNTIFS('작업관리'!$C$3:$C$265,A22,'작업관리'!$F$3:$F$265,"진행 중") | E22: =B22-C22-D22 | F22: - | G22: =IF(B22=0,"",C22/B22)
A23: 시스템·인프라 (Systems & Infra) | B23: =COUNTIFS('작업관리'!$C$3:$C$265,A23) | C23: =COUNTIFS('작업관리'!$C$3:$C$265,A23,'작업관리'!$F$3:$F$265,"완료") | D23: =COUNTIFS('작업관리'!$C$3:$C$265,A23,'작업관리'!$F$3:$F$265,"진행 중") | E23: =B23-C23-D23 | F23: - | G23: =IF(B23=0,"",C23/B23)
A26: 사용법:
A27: - 작업관리 시트에 작업자·상태·완료일시를 입력하면 본 시트와 Content Gantt가 자동 갱신됩니다.
A28: - 오늘 날짜(B3)는 엑셀을 열 때마다 자동 업데이트됩니다.

Sheet 범례
A1: 표기법 안내
A2: M (Milestone) | B2: 개발 단계 — M1 Prototype / M2 Alpha / M3 Early Access / M4 v1.0
A3: Q (Quarter) | B3: 해당 마일스톤 내 분기 (3개월 단위). Q1부터 일련번호로 누적
A4: 예: M2-Q1 | B4: Alpha 단계의 첫 번째 분기 (2026 Q3, 2026-07~09)
A5: 예: M3-Q5 | B5: Early Access 단계의 5번째 분기 (2027 Q3, EA 출시 시점)
A7: 기간별 색상
A9: 기간 | B9: 설명
A10: M1잔여 | B10: 프로토 잔여 (P-23/24/25) — 회색
A11: M2-Q1 | B11: Alpha Q1 (2026 Q3) — 콘텐츠 확장 기반
A12: M2-Q2 | B12: Alpha Q2 (2026 Q4) — 알파 통합·외부 플레이테스트
A13: M3-Q3 | B13: EA Q3 (2027 Q1) — 콘텐츠 확장
A14: M3-Q4 | B14: EA Q4 (2027 Q2) — EA 빌드 준비 + Steam 페이지
A15: M3-Q5 | B15: ★ EA 출시 (2027 Q3)
A16: M3-Q6 | B16: EA 운영·1차 메이저 패치 (2027 Q4)
A17: M4-Q7 | B17: v1.0 Q1 (2028 Q1) — 콘텐츠 풀스택
A18: M4-Q8 | B18: v1.0 Q2 (2028 Q2) — 난이도·접근성
A19: M4-Q9 | B19: v1.0 Q3 (2028 Q3) — 현지화·QA
A20: M4-Q10 | B20: ★ v1.0 정식 출시 (2028 Q4)
... A26: 숫자 기준 | B26: 신규 관문 기준은 내부 탐색 목표다. 업계 평균·판매 예측·기존 G1의 변경이 아니다.

Sheet Claude 작업 이력
A1: Claude 세션 기록 — 종료와 검증 완료는 별도 상태
A2: 원본: Docs/production/agent-board/records.json · 검증대기는 작업판에서 확인
A3: 세션 ID | B3: 작업명 | C3: 작업판 상태 | D3: Claude 상태 | E3: 시작(KST) | F3: 결과 | G3: 검증 근거 | H3: 작업경로 | I3: 대화경로
A4: 91b30430 | B4: Abyss-A 런 안정화 검수 | C4: Completed | D4: failed | E4: 2026-09-22 18:59 | F4: exit 1 before init — Error: Invalid MCP configuration: MCP config file not found: D:\JaeChang\Abyss\Read D:\JaeChang\Abyss\Docs\production\claude-run-20260922\A-prompt.md and carry out that assignment now. | G4: 중단·중복 세션 종결 · 2026-09-30 사용자: 다음 작업 전에 검증을 수행했다고 확인. 이전 중단/실패/중복 세션은 후속 작업으로 이어져 종결. 해당 세션 자체의 테스트 성공을 의미하지 않음. | H4: D:\JaeChang\Abyss
A5: 8a696e23 | B5: Abyss-A 런 안정화 검수 | C5: Completed | D5: done | E5: 2026-09-22 23:37 | F5: kill | G5: 사용자 검증·후속 인수 완료 · 2026-09-30 사용자 과거 작업 검증 완료 확인. memory/SESSION_HISTORY.md 9/28 사용자 검증 및 통합, 9/29 P04 최종 검증 기록이 과거 보고보다 우선. 세션별 AI 실행 테스트 통과로 표기하지 않음. | H5: D:\JaeChang\Abyss | I5: C:\Users\JaeChang\.claude\projects\D--JaeChang-Abyss\8a696e23-fd33-41bb-994a-a5d63e8096a6.jsonl
A6: 03c97093 | B6: Abyss-B 저장 안전성 구현 | C6: Completed | D6: done | E6: 2026-09-22 23:39 | F6: Save-safety refactor complete: atomic writes via .tmp, recovery via .prev, 18 new tests drafted in SaveSystemSafeWriteTests.cs, PlayMode smoke tests +8. Awaiting C's compile/test run and PlayModeSaveGuard audit. | G6: 사용자 검증·후속 인수 완료 · 2026-09-30 사용자 과거 작업 검증 완료 확인. memory/SESSION_HISTORY.md 9/28 사용자 검증 및 통합, 9/29 P04 최종 검증 기록이 과거 보고보다 우선. 세션별 AI 실행 테스트 통과로 표기하지 않음. | H6: D:\JaeChang\Abyss-agent-workspaces\save-safety-20260922 | I6: C:\Users\JaeChang\.claude\projects\D--JaeChang-Abyss-agent-workspaces-save-safety-20260922\03c97093-9d66-443c-988b-252aa324532b.jsonl
A7: b4c3fd74 | B7: Abyss-C Unity 통합 인수 | C7: Completed | D7: stopped | E7: 2026-09-22 23:39 | F7: stopped | G7: 중단·중복 세션 종결 · 2026-09-30 사용자: 다음 작업 전에 검증을 수행했다고 확인. 이전 중단/실패/중복 세션은 후속 작업으로 이어져 종결. 해당 세션 자체의 테스트 성공을 의미하지 않음. | H7: D:\JaeChang\Abyss | I7: C:\Users\JaeChang\.claude\projects\D--JaeChang-Abyss\b4c3fd74-5412-4ffd-af09-c069267a02b5.jsonl
A8: 5c884d9f | B8: Abyss-D 콘텐츠 PD | C8: Completed | D8: stopped | E8: 2026-09-22 23:39 | F8: stopped | G8: 중단·중복 세션 종결 · 2026-09-30 사용자: 다음 작업 전에 검증을 수행했다고 확인. 이전 중단/실패/중복 세션은 후속 작업으로 이어져 종결. 해당 세션 자체의 테스트 성공을 의미하지 않음. | H8: D:\JaeChang\Abyss | I8: C:\Users\JaeChang\.claude\projects\D--JaeChang-Abyss\5c884d9f-f93d-46b2-b960-d523a9c7b4ed.jsonl
A9: d98bd20b | B9: Abyss-E 게임디자인 QA | C9: Completed | D9: stopped | E9: 2026-09-22 23:39 | F9: stopped | G9: 중단·중복 세션 종결 · 2026-09-30 사용자: 다음 작업 전에 검증을 수행했다고 확인. 이전 중단/실패/중복 세션은 후속 작업으로 이어져 종결. 해당 세션 자체의 테스트 성공을 의미하지 않음. | H9: D:\JaeChang\Abyss | I9: C:\Users\JaeChang\.claude\projects\D--JaeChang-Abyss\d98bd20b-8344-4a72-a9ae-04215d0adb87.jsonl
A10: ccf08da3 | B10: git worktree report setup | C10: Completed | D10: done | E10: 2026-09-22 23:39 | F10: Code review of run-abandon feature completed; report at D:/JaeChang/Abyss-agent-workspaces/review-20260922/Docs/production/results/A-run-flow.md. Found 3 issues: [mid] unpause during title fade allows timeScale=0 lobby load; [low] test hardcodes gold to 0; [escalate] analytics can't distinguish abandoned runs. | G10: 사용자 검증·후속 인수 완료 · 2026-09-30 사용자 과거 작업 검증 완료 확인. memory/SESSION_HISTORY.md 9/28 사용자 검증 및 통합, 9/29 P04 최종 검증 기록이 과거 보고보다 우선. 세션별 AI 실행 테스트 통과로 표기하지 않음. | H10: D:\JaeChang\Abyss | I10: C:\Users\JaeChang\.claude\projects\D--JaeChang-Abyss\ccf08da3-3010-4dd4-9ae5-a41c42161a77.jsonl
A11: 00d47837 | B11: Continue your assigned task from the existing context. The coordinator has created a linked git worktree for report isolation. IMPORTANT: write your only report to D:/JaeChang/Abyss-agent-workspaces/review-20260922/Docs/production/results/C-integration.md instead of the original shared checkout. Read original D:/JaeChang/Abyss sources for the CURRENT working state; another worker has committed changes meanwhile, so describe current evidence and do not assume the old bug is still open. You may read/write ONLY your assigned report under the linked worktree; do not edit any source or other report. Do not change or disable the background isolation guard. Do not spawn agents or run Unity. Continue now and finish the report; label unexecuted tests honestly. | C11: Completed | D11: stopped | E11: 2026-09-22 23:39 | F11: stopped | G11: 중단·중복 세션 종결 · 2026-09-30 사용자: 다음 작업 전에 검증을 수행했다고 확인. 이전 중단/실패/중복 세션은 후속 작업으로 이어져 종결. 해당 세션 자체의 테스트 성공을 의미하지 않음. | H11: D:\JaeChang\Abyss
A12: 17283e86 | B12: Continue your assigned task from the existing context. The coordinator has created a linked git worktree for report isolation. IMPORTANT: write your only report to D:/JaeChang/Abyss-agent-workspaces/review-20260922/Docs/production/results/D-stage1-direction.md instead of the original shared checkout. Read original D:/JaeChang/Abyss sources for the CURRENT working state; another worker has committed changes meanwhile, so describe current evidence and do not assume the old bug is still open. You may read/write ONLY your assigned report under the linked worktree; do not edit any source or other report. Do not change or disable the background isolation guard. Do not spawn agents or run Unity. Continue now and finish the report; label unexecuted tests honestly. | C12: Completed | D12: stopped | E12: 2026-09-22 23:40 | F12: stopped | G12: 중단·중복 세션 종결 · 2026-09-30 사용자: 다음 작업 전에 검증을 수행했다고 확인. 이전 중단/실패/중복 세션은 후속 작업으로 이어져 종결. 해당 세션 자체의 테스트 성공을 의미하지 않음. | H12: D:\JaeChang\Abyss
A13: 30497735 | B13: Continue your assigned task from the existing context. The coordinator has created a linked git worktree for report isolation. IMPORTANT: write your only report to D:/JaeChang/Abyss-agent-workspaces/review-20260922/Docs/production/results/E-test-plan.md instead of the original shared checkout. Read original D:/JaeChang/Abyss sources for the CURRENT working state; another worker has committed changes meanwhile, so describe current evidence and do not assume the old bug is still open. You may read/write ONLY your assigned report under the linked worktree; do not edit any source or other report. Do not change or disable the background isolation guard. Do not spawn agents or run Unity. Continue now and finish the report; label unexecuted tests honestly. | C13: Completed | D13: stopped | E13: 2026-09-22 23:40 | F13: stopped | G13: 중단·중복 세션 종결 · 2026-09-30 사용자: 다음 작업 전에 검증을 수행했다고 확인. 이전 중단/실패/중복 세션은 후속 작업으로 이어져 종결. 해당 세션 자체의 테스트 성공을 의미하지 않음. | H13: D:\JaeChang\Abyss
A14: 5a203014 | B14: Abyss-C Unity 통합 인수 | C14: Completed | D14: done | E14: 2026-09-22 23:41 | F14: Report: C-integration.md in review-20260922 worktree. Stage 1 data linked correctly; 27 environment assets disconnected from Run scene; BossAbyssKeeper temp sprite needs final art. | G14: 사용자 검증·후속 인수 완료 · 2026-09-30 사용자 과거 작업 검증 완료 확인. memory/SESSION_HISTORY.md 9/28 사용자 검증 및 통합, 9/29 P04 최종 검증 기록이 과거 보고보다 우선. 세션별 AI 실행 테스트 통과로 표기하지 않음. | H14: D:\JaeChang\Abyss | I14: C:\Users\JaeChang\.claude\projects\D--JaeChang-Abyss\5a203014-b96c-4b23-8a11-4295a8341be2.jsonl
A15: 883122ad | B15: Abyss-D 콘텐츠 PD | C15: Completed | D15: done | E15: 2026-09-22 23:41 | F15: D-stage1-direction.md: 27-frame art unhooked from Run scene, boss sprite is placeholder, 5 enemy types reusable, 21 SFX Python-generated + connected, 0 BGM; 4 decisions needed from leadership | G15: 사용자 검증·후속 인수 완료 · 2026-09-30 사용자 과거 작업 검증 완료 확인. memory/SESSION_HISTORY.md 9/28 사용자 검증 및 통합, 9/29 P04 최종 검증 기록이 과거 보고보다 우선. 세션별 AI 실행 테스트 통과로 표기하지 않음. | H15: D:\JaeChang\Abyss | I15: C:\Users\JaeChang\.claude\projects\D--JaeChang-Abyss\883122ad-2a76-451f-be22-747e8f5f7a78.jsonl
A16: d0a0802e | B16: Abyss-E 게임디자인 QA | C16: Completed | D16: done | E16: 2026-09-22 23:41 | F16: Test plan documented (R/T1/T2 branches, 12 instrumentation bugs identified, 5 decision items for stakeholders, past sample segregated) | G16: 사용자 검증·후속 인수 완료 · 2026-09-30 사용자 과거 작업 검증 완료 확인. memory/SESSION_HISTORY.md 9/28 사용자 검증 및 통합, 9/29 P04 최종 검증 기록이 과거 보고보다 우선. 세션별 AI 실행 테스트 통과로 표기하지 않음. | H16: D:\JaeChang\Abyss | I16: C:\Users\JaeChang\.claude\projects\D--JaeChang-Abyss\d0a0802e-9afb-4629-88eb-c10bbbdc4264.jsonl
A17: 4ac109f1 | B17: save system verification | C17: Completed | D17: stopped | E17: 2026-09-23 00:09 | F17: stopped | G17: 중단·중복 세션 종결 · 2026-09-30 사용자: 다음 작업 전에 검증을 수행했다고 확인. 이전 중단/실패/중복 세션은 후속 작업으로 이어져 종결. 해당 세션 자체의 테스트 성공을 의미하지 않음. | H17: D:\JaeChang\Abyss-agent-workspaces\save-safety-20260922 | I17: C:\Users\JaeChang\.claude\projects\D--JaeChang-Abyss-agent-workspaces-save-safety-20260922\4ac109f1-21b7-43e4-a944-0f5546c5044a.jsonl
A18: 47d01473 | B18: Abyss-A2 후속 구현 | C18: Completed | D18: done | E18: 2026-09-23 00:09 | F18: A2-event-contract.md + A2-run-transition.md in Docs/production/results/; awaiting C compile & R1-R5 verification | G18: 사용자 검증·후속 인수 완료 · 2026-09-30 사용자 과거 작업 검증 완료 확인. memory/SESSION_HISTORY.md 9/28 사용자 검증 및 통합, 9/29 P04 최종 검증 기록이 과거 보고보다 우선. 세션별 AI 실행 테스트 통과로 표기하지 않음. | H18: D:\JaeChang\Abyss-agent-workspaces\run-transition-20260923 | I18: C:\Users\JaeChang\.claude\projects\D--JaeChang-Abyss-agent-workspaces-run-transition-20260923\47d01473-c425-4f0e-b7fe-4c8d829d3a85.jsonl
A19: c3801c1b | B19: Abyss-E2 후속 구현 | C19: Completed | D19: done | E19: 2026-09-23 00:09 | F19: E2 analytics implementation complete. Report at Docs/production/results/E2-analytics.md; synthetic test logs in E2-synthetic-logs/; awaiting Codex to run commands ①~④ and validate. | G19: 사용자 검증·후속 인수 완료 · 2026-09-30 사용자 과거 작업 검증 완료 확인. memory/SESSION_HISTORY.md 9/28 사용자 검증 및 통합, 9/29 P04 최종 검증 기록이 과거 보고보다 우선. 세션별 AI 실행 테스트 통과로 표기하지 않음. | H19: D:\JaeChang\Abyss-agent-workspaces\analytics-20260923 | I19: C:\Users\JaeChang\.claude\projects\D--JaeChang-Abyss-agent-workspaces-analytics-20260923\c3801c1b-3612-4e1c-9a48-d64c5cba74c5.jsonl
A20: 3dc4c0ee | B20: 작업공간: D:/JaeChang/Abyss-agent-workspaces/review-20260922 사용자가 후속 실행을 승인했다. 총괄은 Codex다. 원본 D:/JaeChang/Abyss는 읽기만 가능하다. 지정 linked worktree에서만 배정 파일을 수정하라. 커밋/병합/푸시/다른 에이전트 실행/사용자 저장 접근/Unity 실행은 하지 않는다. .meta는 직접 생성하지 않는다. 공통 memory/간트 갱신은 총괄 소유이므로 하지 않는다. 결과는 자신의 작업공간 Docs/production/results에 제출한다. 불가능한 검증은 미실행으로 표시한다. 먼저 CONVENTIONS.md를 읽어라. 원본 참조, 모든 산출물은 D:/JaeChang/Abyss-agent-workspaces/review-20260922/Docs/production/results에 작성하라. 문서 작성만 하라. 첫 보스와 최소 사운드의 구현 계약 > 기존 D 명세를 유지하되 BossAbyssKeeper의 예고·발동·회복 규약을 먼저 작성하라. 현재 windup/recovery 0과 기본 탄막의 예고 부재를 구분해 적어라. 보스 신규 외형 제작으로 공격 예고가 해결된다고 가정하지 마라. > > 근접/탄막 각각 플레이어가 무엇을 보고 반응할지, 어떤 구간에 피해가 발생하는지, 임시 표현으로 어떻게 확인할지 제시하라. 수치 제안은 제안으로 표시하고 EnemyData나 코드를 직접 수정하지 않는다. 공용 BossEnemy 변경이 다른 보스에 영향을 주는지 C가 판단할 수 있게 한다. > > 첫 범위는 Stage1 기존 배경·지면·발판 재사용, 현재 지형 보존이다. 피격·폼교체·가드 소리 중 기존 자산 재사용으로 확인 가능한 것과 신규 음원이 필요한 것을 구분한다. 보스 전량 제작/새 음악 구매/유료 생성은 하지 않는다. 정상 화면·청취 검증이 없는 항목을 합격 처리하지 마라. > > 결과 D2-boss-feedback.md를 C가 사용할 대상 파일·타이밍·시각/청각 통과 조건으로 작성하라. | C20: Completed | D20: stopped | E20: 2026-09-23 00:09 | F20: stopped | G20: 중단·중복 세션 종결 · 2026-09-30 사용자: 다음 작업 전에 검증을 수행했다고 확인. 이전 중단/실패/중복 세션은 후속 작업으로 이어져 종결. 해당 세션 자체의 테스트 성공을 의미하지 않음. | H20: D:\JaeChang\Abyss-agent-workspaces\review-20260922 | I20: C:\Users\JaeChang\.claude\projects\D--JaeChang-Abyss-agent-workspaces-review-20260922\3dc4c0ee-9837-4c0c-82cb-90a1bab721d4.jsonl
A21: bcba50da | B21: save system validation | C21: Completed | D21: done | E21: 2026-09-23 00:10 | F21: B2 followup complete: SaveFileOperations.cs + MetaSaveService.LoadState.cs with guard contract & inaccessible-vs-corrupt split, 20 tests (8 EditMode + 12 PlayMode), handoff doc at Docs/production/results/B2-save-safety-followup.md | G21: 사용자 검증·후속 인수 완료 · 2026-09-30 사용자 과거 작업 검증 완료 확인. memory/SESSION_HISTORY.md 9/28 사용자 검증 및 통합, 9/29 P04 최종 검증 기록이 과거 보고보다 우선. 세션별 AI 실행 테스트 통과로 표기하지 않음. | H21: D:\JaeChang\Abyss-agent-workspaces\save-safety-20260922 | I21: C:\Users\JaeChang\.claude\projects\D--JaeChang-Abyss-agent-workspaces-save-safety-20260922\bcba50da-bf39-40cd-bd64-7de0ec1bc43b.jsonl
A22: ea6df2c1 | B22: sfx audiomanager integration | C22: Completed | D22: done | E22: 2026-09-23 00:11 | F22: D2-boss-feedback.md: melee/volley telegraph analysis + 4 decisions for Codex (stagger interrupt scope, sfx ownership, values, simultaneous attack block) | G22: 사용자 검증·후속 인수 완료 · 2026-09-30 사용자 과거 작업 검증 완료 확인. memory/SESSION_HISTORY.md 9/28 사용자 검증 및 통합, 9/29 P04 최종 검증 기록이 과거 보고보다 우선. 세션별 AI 실행 테스트 통과로 표기하지 않음. | H22: D:\JaeChang\Abyss-agent-workspaces\review-20260922 | I22: C:\Users\JaeChang\.claude\projects\D--JaeChang-Abyss-agent-workspaces-review-20260922\ea6df2c1-431b-42b8-9dc5-712981a2b7e7.jsonl
A23: 4da7849a | B23: A2 결과 인수 검수에서 보완 2건. D:/JaeChang/Abyss/Docs/production/wave2-20260923/coordinator-review.md A2 항목을 읽고 보완하라. 특히 미등록 씬 예외에서 검은 화면 복구와 AbandonRun 구독자 예외에도 골드 0 불변식 보장. 해당 회귀 테스트를 추가하고 기존 결과문서에 보완 기록. 범위 외 변경 금지, Unity 실행/커밋 금지. | C23: Completed | D23: stopped | E23: 2026-09-23 15:50 | F23: stopped | G23: 중단·중복 세션 종결 · 2026-09-30 사용자: 다음 작업 전에 검증을 수행했다고 확인. 이전 중단/실패/중복 세션은 후속 작업으로 이어져 종결. 해당 세션 자체의 테스트 성공을 의미하지 않음. | H23: D:\JaeChang\Abyss-agent-workspaces\run-transition-20260923 | I23: C:\Users\JaeChang\.claude\projects\D--JaeChang-Abyss-agent-workspaces-run-transition-20260923\4da7849a-2ee7-4905-9565-d2d7b0e46759.jsonl
A24: 06983306 | B24: B2 결과 중 런타임 2개 파일 분할은 승인한다. D:/JaeChang/Abyss/Docs/production/wave2-20260923/coordinator-review.md B2 항목을 읽고 보완하라. 중첩 Acquire는 이미 활성인 가드를 자동 해제하지 말고 예외로 거절하라. 테스트도 두 독립 가드의 실제 중첩/순서로 검증하여 첫 가드 격리가 살아 있음을 확인하라. 기존 누수 자동 회복 기대는 제거하라. 파일 범위 유지, Unity 실행/커밋 금지. 보고서에 보완 기록. | C24: Completed | D24: stopped | E24: 2026-09-23 15:50 | F24: stopped | G24: 중단·중복 세션 종결 · 2026-09-30 사용자: 다음 작업 전에 검증을 수행했다고 확인. 이전 중단/실패/중복 세션은 후속 작업으로 이어져 종결. 해당 세션 자체의 테스트 성공을 의미하지 않음. | H24: D:\JaeChang\Abyss-agent-workspaces\save-safety-20260922 | I24: C:\Users\JaeChang\.claude\projects\D--JaeChang-Abyss-agent-workspaces-save-safety-20260922\06983306-4940-4ab8-af68-d1b8ee1e57d3.jsonl
A25: e0fb533a | B25: Abyss-C2 통합 구현 | C25: Completed | D25: stopped | E25: 2026-09-23 15:51 | F25: stopped | G25: 중단·중복 세션 종결 · 2026-09-30 사용자: 다음 작업 전에 검증을 수행했다고 확인. 이전 중단/실패/중복 세션은 후속 작업으로 이어져 종결. 해당 세션 자체의 테스트 성공을 의미하지 않음. | H25: D:\JaeChang\Abyss-agent-workspaces\integration-20260923 | I25: C:\Users\JaeChang\.claude\projects\D--JaeChang-Abyss-agent-workspaces-integration-20260923\e0fb533a-9dc9-4a4d-b51c-1097e22bd842.jsonl
A26: d5766c7d | B26: run manager code review | C26: Completed | D26: stopped | E26: 2026-09-23 15:54 | F26: stopped | G26: 중단·중복 세션 종결 · 2026-09-30 사용자: 다음 작업 전에 검증을 수행했다고 확인. 이전 중단/실패/중복 세션은 후속 작업으로 이어져 종결. 해당 세션 자체의 테스트 성공을 의미하지 않음. | H26: D:\JaeChang\Abyss | I26: C:\Users\JaeChang\.claude\projects\D--JaeChang-Abyss\d5766c7d-ecd9-4266-95f9-a7b235752470.jsonl
A27: ed7b46ff | B27: save system testing | C27: Completed | D27: done | E27: 2026-09-23 15:54 | G27: 사용자 검증·후속 인수 완료 · 2026-09-30 사용자 과거 작업 검증 완료 확인. memory/SESSION_HISTORY.md 9/28 사용자 검증 및 통합, 9/29 P04 최종 검증 기록이 과거 보고보다 우선. 세션별 AI 실행 테스트 통과로 표기하지 않음. | H27: D:\JaeChang\Abyss | I27: C:\Users\JaeChang\.claude\projects\D--JaeChang-Abyss\ed7b46ff-5724-4efa-a412-7fd9fda4a14d.jsonl
A28: 48b1f9b7 | B28: login recovery c2 assignment | C28: Completed | D28: stopped | E28: 2026-09-23 15:54 | F28: stopped | G28: 중단·중복 세션 종결 · 2026-09-30 사용자: 다음 작업 전에 검증을 수행했다고 확인. 이전 중단/실패/중복 세션은 후속 작업으로 이어져 종결. 해당 세션 자체의 테스트 성공을 의미하지 않음. | H28: D:\JaeChang\Abyss | I28: C:\Users\JaeChang\.claude\projects\D--JaeChang-Abyss\48b1f9b7-22a1-4f16-959d-c064fbbc421d.jsonl
A29: c55e0c52 | B29: run transition code review | C29: Completed | D29: stopped | E29: 2026-09-23 15:54 | F29: stopped | G29: 중단·중복 세션 종결 · 2026-09-30 사용자: 다음 작업 전에 검증을 수행했다고 확인. 이전 중단/실패/중복 세션은 후속 작업으로 이어져 종결. 해당 세션 자체의 테스트 성공을 의미하지 않음. | H29: D:\JaeChang\Abyss-agent-workspaces\run-transition-20260923 | I29: C:\Users\JaeChang\.claude\projects\D--JaeChang-Abyss-agent-workspaces-run-transition-20260923\c55e0c52-9c1b-45ae-afe1-b06e5a53075e.jsonl
A30: 9bcff2b2 | B30: save system testing implementation | C30: Completed | D30: done | E30: 2026-09-23 15:55 | F30: PlayModeSaveGuard nested-acquire rejection & forced-release tests; TryReadFile access-denial reclassification; guard-leak & permission-exception risks documented in §6 | G30: 사용자 검증·후속 인수 완료 · 2026-09-30 사용자 과거 작업 검증 완료 확인. memory/SESSION_HISTORY.md 9/28 사용자 검증 및 통합, 9/29 P04 최종 검증 기록이 과거 보고보다 우선. 세션별 AI 실행 테스트 통과로 표기하지 않음. | H30: D:\JaeChang\Abyss-agent-workspaces\save-safety-20260922 | I30: C:\Users\JaeChang\.claude\projects\D--JaeChang-Abyss-agent-workspaces-save-safety-20260922\9bcff2b2-ff03-4af9-bbd1-bc94cdea93cb.jsonl
A31: f88c4330 | B31: resume workspace integration | C31: Completed | D31: stopped | E31: 2026-09-23 15:55 | F31: first boss telegraph system + Stage1 environment wiring complete; awaiting Unity validation | G31: 사용자 검증·후속 인수 완료 · 2026-09-30 사용자 과거 작업 검증 완료 확인. memory/SESSION_HISTORY.md 9/28 사용자 검증 및 통합, 9/29 P04 최종 검증 기록이 과거 보고보다 우선. 세션별 AI 실행 테스트 통과로 표기하지 않음. | H31: D:\JaeChang\Abyss-agent-workspaces\integration-20260923 | I31: C:\Users\JaeChang\.claude\projects\D--JaeChang-Abyss-agent-workspaces-integration-20260923\f88c4330-dd1c-41d4-8624-8096041df453.jsonl
A32: 405cb3ed | B32: analytics terminal editor flag | C32: Completed | D32: done | E32: 2026-09-28 18:18 | F32: AnalyticsTerminalPlayModeSmoke.cs:102 fixed; player-test-fix.md awaits paste; tests remain | G32: 사용자 검증·후속 인수 완료 · 2026-09-30 사용자 과거 작업 검증 완료 확인. memory/SESSION_HISTORY.md 9/28 사용자 검증 및 통합, 9/29 P04 최종 검증 기록이 과거 보고보다 우선. 세션별 AI 실행 테스트 통과로 표기하지 않음. | H32: D:\JaeChang\Abyss | I32: C:\Users\JaeChang\.claude\projects\D--JaeChang-Abyss\405cb3ed-8316-4f27-aa9f-d0ad2b8b18f8.jsonl
A33: 2e213a67 | B33: next tasks handoff | C33: Completed | D33: done | E33: 2026-09-28 18:38 | F33: 세션 기록과 인수인계를 정리했습니다. P03은 브랜치에만 푸시돼 develop 병합을 기다리고, 미커밋으로 남은 파일은 제 작업이 아닌 `ProjectSettings.asset` 하나입니다. | G33: 사용자 검증·후속 인수 완료 · 2026-09-30 사용자 과거 작업 검증 완료 확인. memory/SESSION_HISTORY.md 9/28 사용자 검증 및 통합, 9/29 P04 최종 검증 기록이 과거 보고보다 우선. 세션별 AI 실행 테스트 통과로 표기하지 않음. | H33: D:\JaeChang\Abyss | I33: C:\Users\JaeChang\.claude\projects\D--JaeChang-Abyss\2e213a67-7d44-4192-b848-d7fa3a486222.jsonl
A34: 15bf111c | B34: read-only investigation assignment | C34: Completed | D34: done | E34: 2026-09-29 01:27 | F34: Read-only analysis complete: 3 implementation candidates ranked (recommend Candidate 1: guard-entry swap); 9 unresolved design decisions block scope lock (trigger condition, entry effect type, counterattack sequencing, cooldown handling, logging strategy, test enemy placement, visual feedback, doc gaps) | G34: 사용자 검증·후속 인수 완료 · 2026-09-30 사용자 과거 작업 검증 완료 확인. memory/SESSION_HISTORY.md 9/28 사용자 검증 및 통합, 9/29 P04 최종 검증 기록이 과거 보고보다 우선. 세션별 AI 실행 테스트 통과로 표기하지 않음. | H34: D:\JaeChang\Abyss | I34: C:\Users\JaeChang\.claude\projects\D--JaeChang-Abyss\15bf111c-6dd8-44de-8e69-7be156ae25e5.jsonl
A35: a004ca55 | B35: implementation assignment a/b/c | C35: Completed | D35: done | E35: 2026-09-29 01:35 | F35: Implementation complete: A (guard swap reserve), B (ranged-to-melee lunge), C (ranged mark). See Docs/production/p04-20260929/implementation-result.md for full spec, toggles in RunConfig.asset, and manual validation checklist. | G35: 사용자 검증·후속 인수 완료 · 2026-09-30 사용자 과거 작업 검증 완료 확인. memory/SESSION_HISTORY.md 9/28 사용자 검증 및 통합, 9/29 P04 최종 검증 기록이 과거 보고보다 우선. 세션별 AI 실행 테스트 통과로 표기하지 않음. | H35: D:\JaeChang\Abyss | I35: C:\Users\JaeChang\.claude\projects\D--JaeChang-Abyss\a004ca55-eba8-4ba1-ad72-c1d219292e21.jsonl
A36: 63f1a6f9 | B36: p04 read-only review | C36: Completed | D36: done | E36: 2026-09-29 01:35 | F36: A/B 입력예약·교체·물리이동 설계의 5대 위험(폼 데이터 동기화, 예약 중복/미삭제, 접근 충돌 해제 누락, 대시 효과 중복, 프레임락 접지판정)과 10항 인수조건 정적 근거 검토 완료. 구현자 수정 대기. | G36: 사용자 검증·후속 인수 완료 · 2026-09-30 사용자 과거 작업 검증 완료 확인. memory/SESSION_HISTORY.md 9/28 사용자 검증 및 통합, 9/29 P04 최종 검증 기록이 과거 보고보다 우선. 세션별 AI 실행 테스트 통과로 표기하지 않음. | H36: D:\JaeChang\Abyss | I36: C:\Users\JaeChang\.claude\projects\D--JaeChang-Abyss\63f1a6f9-a7ac-4790-bf9f-4780411466cf.jsonl
A37: 7276e64c | B37: p04 code connection review | C37: Completed | D37: done | E37: 2026-09-29 01:35 | F37: P04 C projectile marking system review finished: identified 5 critical issues (stagger effect, tier filtering, generation tracking, consumption logic, visual conflicts) + 8 acceptance criteria; awaiting implementer decisions on stagger and tier filtering | G37: 사용자 검증·후속 인수 완료 · 2026-09-30 사용자 과거 작업 검증 완료 확인. memory/SESSION_HISTORY.md 9/28 사용자 검증 및 통합, 9/29 P04 최종 검증 기록이 과거 보고보다 우선. 세션별 AI 실행 테스트 통과로 표기하지 않음. | H37: D:\JaeChang\Abyss | I37: C:\Users\JaeChang\.claude\projects\D--JaeChang-Abyss\7276e64c-3549-4f15-b948-abc17a622187.jsonl
A38: a1f3dfb8 | B38: visual feedback implementation a/b | C38: Completed | D38: done | E38: 2026-09-29 02:10 | F38: FormComboPlayerFx.cs + FormComboSprites.cs created; A swap ring+blink, B wedge+speed-lines wired; result doc at feedback-result.md | G38: 사용자 검증·후속 인수 완료 · 2026-09-30 사용자 과거 작업 검증 완료 확인. memory/SESSION_HISTORY.md 9/28 사용자 검증 및 통합, 9/29 P04 최종 검증 기록이 과거 보고보다 우선. 세션별 AI 실행 테스트 통과로 표기하지 않음. | H38: D:\JaeChang\Abyss | I38: C:\Users\JaeChang\.claude\projects\D--JaeChang-Abyss\a1f3dfb8-2118-490b-9b0c-eaa1620a0b74.jsonl
